Workbook

Sheet PRUEBA
C1: IDENTIFICACION | F1: IR.1.1.10 Al finalizar el Programa, 540 familias de los municipios de LC, SSY y SRN tienen acceso a agua potable de calidad de forma continuo y sostenible. | N1: IR.1.1.13 Al finalizar el programa 24 CAPS de la zona de intervención han entregado al INAA todos los requisitos para su legalización, según el procedimiento de la ley 722 de CAPS. IR.1.1.21 12 CAPS con participación de al menos un 50% de mujeres en la toma de decisiones | W1: IR.1.1.16 24 CAPS logran mantener como mínimo un 10% extra sobre sus costos de funcionamiento mensual. | Z1: IR.1.1.17 24 CAPS cuentan e implementan un plan de operación y mantenimiento… | AJ1: IR.1.1.14 24 CAPS realizan asambleas comunitarias de rendición de cuentas conforme a su Reglamento Interno. | AU1: IR.1.1.20 24 CAPS recogen en sus planes de acción y reglamento interno medidas y acciones positivas dirigidas a promover la participación activa de las mujeres | AX1: IR.1.1.10 Al finalizar el Programa, 540 familias de los municipios de LC, SSY y SRN tienen acceso a agua potable de calidad de forma continuo y sostenible.
A2: HOJAS RELACIONADAS PARA REGRESAR HAGA CLICK è | F2: Utilizar Hoja Org_CAPS | N2: Hoja "Entrevista_CAPS" | U2: Hoja Gestión_ CAPS | W2: Hoja " Entrevista_CAPS" | AN2: Hoja " Est_Conservación" | AU2: IR.1.1.20Género!A1 | AX2: Ind.Sostenib.!A1 | BD2: INSTRUCCIONES PARA EL CALCULO DEL INDICE DE SOSTENIBILIDAD
A3: Municipio | B3: Microregión /Distrito | C3: Comunidad/CAPS | D3: Tipo de Sistema | E3: Tiempo de Conformación | F3: A.Organización | N3: B.Capital Social | U3: C.Autogestión | W3: D.Recuperación de costes | Z3: E.Operación & Mantenimiento | AC3: F.Salud Comunitaria y Ambiental | AJ3: G.Rendición de cuentas | AN3: H.Estado y conservación sistema | AU3: I.Incorporacion del enfoque de Gènero | AX3: Indice de Sostenibilidad MABE | BA3: Indice de Sostenbilidad MAG
F4: nº miembros totales | G4: Val | H4: Legalización | I4: 50% particip. Mujeres | J4: Val | K4: Capacidad Convocatoria | L4: Val | M4: A | N4: Red CAPs | O4: CMC | P4: COMACO | Q4: CMR | R4: CPC | S4: CAS | T4: B | U4: C1 | V4: Val | W4: D1 | X4: D2 | Y4: D | Z4: E1 | AA4: E2 | AB4: E | AC4: F1 | AD4: F2 | AE4: F3 | AF4: F4 | AG4: F5 | AH4: F6 | AI4: F | AJ4: G1 | AK4: G2 | AL4: G3 | AM4: G | AN4: H1 | AO4: Val | AP4: H2 | AQ4: Val | AR4: H3 | AS4: H4 | AT4: H | AU4: A | AV4: B | AW4: I | AX4: 0-5 años | AY4: 5-10 años | AZ4: màs de 10 años | BA4: 0-5 años | BB4: 5-10 años | BC4: màs de 10 años
A5: SRN | B5: 1 | C5: 1- El Diamante/ San Martin | D5: MABE | E5: mas de 10 años | F5: 9 | G5: =IF(F5>=4,1,IF(F5<4,0)) -> 1 | H5: 1 | I5: 0.44 | J5: =IF(I5>=0.5,1,0) -> 0 | K5: 3 | L5: =IF(K5>=2,1,IF(K5<2,0)) -> 1 | M5: =SUM(G5*0.2+H5*0.3+J5*0.2+L5*0.3) -> 0.8 | N5: 1 | O5: 1 | P5: 0 | Q5: 0 | R5: 1 | S5: 1 | T5: =IF((N5+O5+P5+Q5+S5)>=2,1,IF((N5+O5+P5+Q5+S5)<2,0)) -> 1 | U5: 3 | V5: =IF(U5>=2,1,IF(U5<2,0)) -> 1 | W5: 1 | X5: 1 | Y5: =IF((W5+X5)=2,1,IF((W5+X5)<2,0)) -> 1 | Z5: 0 | AA5: 0 | AB5: =Z5*AA5 -> 0 | AC5: 0 | AD5: 1 | AE5: 1 | AF5: 1 | AG5: 0 | AH5: 1 | AI5: =IF(SUM(AC5:AH5)>=3,1,IF(SUM(AC5:AH5)<3,0)) -> 1 | AJ5: 1 | AK5: 1 | AL5: 1 | AM5: =IF(SUM(AJ5:AL5)>=3,1,IF(SUM(AJ5:AL5)<3,0)) -> 1 | AN5: 5 | AO5: =IF(AN5>=3,1,0) -> 1 | AP5: 5 | AQ5: =IF(AP5>=4,1,0) -> 1 | AR5: 0 | AS5: 1 | AT5: =(AO5*0.3)+(AQ5*0.3)+(AR5*0.2)+(AS5*0.2) -> 0.8 | AU5: 0 | AV5: 0 | AW5: =+(AU5*0.6)+(AV5*0.4) -> 0 | AZ5: =((M5*0.1)+(T5*0.05)+(V5*0.2)+(Y5*0.2)+(AB5*0.15)+(AI5*0.05)+(AM5*0.1)+(AT5*0.05)+(AW5*0.1)*100) -> 0.72 | BD5: Para el càlculo del Indice de la sostenibilidad de los sistemas se utilizará la tabla de la hoja Indic_sostenibilidad ( porcentajes según el sistema y conservación construcción),la fórmula a colocar será la suma de la ùltima columna, ejemplo la A,B,C.... H de cada medición pòr el porcentaje correspondiente segùn tabla de indicadores. Para ejemplificar: ((M6*0,15)+(T6*0,05)+(V6+0,15)+(Y6*0,15)+(AB6*0,15)+(AI6*0,15)+(AM6*0,05)+(AT6*0,10)+(AW6*0,10)+100)
A6: SRN | C6: 2- La Breiera | D6: MAG | E6: 5 - 10 años | F6: 6 | G6: =IF(F6>=4,1,IF(F6<4,0)) -> 1 | H6: 0 | I6: 0.55 | J6: =IF(I6>=0.5,1,0) -> 1 | K6: 5 | L6: =IF(K6>=2,1,IF(K6<2,0)) -> 1 | M6: =SUM(G6*0.2+H6*0.3+J6*0.2+L6*0.3) -> 0.7 | N6: 1 | O6: 0 | P6: 0 | Q6: 0 | R6: 1 | S6: 1 | T6: =IF((N6+O6+P6+Q6+S6)>=2,1,IF((N6+O6+P6+Q6+S6)<2,0)) -> 1 | U6: 3 | V6: =IF(U6>=2,1,IF(U6<2,0)) -> 1 | W6: 0 | X6: 1 | Y6: =IF((W6+X6)=2,1,IF((W6+X6)<2,0)) -> 0 | Z6: 0 | AA6: 1 | AB6: =Z6*AA6 -> 0 | AC6: 0 | AD6: 1 | AE6: 0 | AF6: 1 | AG6: 1 | AH6: 0 | AI6: =IF(SUM(AC6:AH6)>=3,1,IF(SUM(AC6:AH6)<3,0)) -> 1 | AJ6: 0 | AK6: 1 | AL6: 1 | AM6: =IF(SUM(AJ6:AL6)>=3,1,IF(SUM(AJ6:AL6)<3,0)) -> 0 | AN6: 2 | AO6: =IF(AN6>=3,1,0) -> 0 | AP6: 6 | AQ6: =IF(AP6>=4,1,0) -> 1 | AR6: 0 | AS6: 1 | AT6: =(AO6*0.3)+(AQ6*0.3)+(AR6*0.2)+(AS6*0.2) -> 0.5 | AU6: 0 | AV6: 0 | AW6: =+(AU6*0.6)+(AV6*0.4) -> 0 | BB6: =((M6*0.15)+(T6*0.05)+(V6*0.15)+(Y6*0.15)+(AB6*0.15)+(AI6*0.1)+(AM6*0.1)+(AT6*0.05)+(AW6*0.1)*100) -> 0.43
A7: SRN | C7: 3- Valle de Suni | D7: MABE | E7: 0 - 5 años | F7: 6 | G7: =IF(F7>=4,1,IF(F7<4,0)) -> 1 | I7: 0.5 | J7: =IF(I7>=0.5,1,0) -> 1 | L7: =IF(K7>=2,1,IF(K7<2,0)) -> 0 | M7: =SUM(G7*0.2+H7*0.3+J7*0.2+L7*0.3) -> 0.4 | T7: =IF((N7+O7+P7+Q7+S7)>=2,1,IF((N7+O7+P7+Q7+S7)<2,0)) -> 0 | V7: =IF(U7>=2,1,IF(U7<2,0)) -> 0 | Y7: =IF((W7+X7)=2,1,IF((W7+X7)<2,0)) -> 0 | AB7: =Z7*AA7 -> 0 | AI7: =IF(SUM(AC7:AH7)>=3,1,IF(SUM(AC7:AH7)<3,0)) -> 0 | AM7: =IF(SUM(AJ7:AL7)>=3,1,IF(SUM(AJ7:AL7)<3,0)) -> 0 | AO7: =IF(AN7>=3,1,0) -> 0 | AQ7: =IF(AP7>=4,1,0) -> 0 | AT7: =(AO7*0.3)+(AQ7*0.3)+(AR7*0.2)+(AS7*0.2) -> 0 | AV7: 0 | AW7: =+(AU7*0.6)+(AV7*0.4) -> 0 | AX7: =((M7*0.15)+(T7*0.05)+(V7*0.15)+(Y7*0.15)+(AB7*0.15)+(AI7*0.05)+(AM7*0.1)+(AT7*0.1)+(AW7*0.1)*100) -> 0.06
A8: SRN | C8: 4- El Espino | D8: MAG | E8: mas de 10 años | G8: =IF(F8>=4,1,IF(F8<4,0)) -> 0 | J8: =IF(I8>=0.5,1,0) -> 0 | L8: =IF(K8>=2,1,IF(K8<2,0)) -> 0 | M8: =SUM(G8*0.2+H8*0.3+J8*0.2+L8*0.3) -> 0 | T8: =IF((N8+O8+P8+Q8+S8)>=2,1,IF((N8+O8+P8+Q8+S8)<2,0)) -> 0 | V8: =IF(U8>=2,1,IF(U8<2,0)) -> 0 | Y8: =IF((W8+X8)=2,1,IF((W8+X8)<2,0)) -> 0 | AB8: =Z8*AA8 -> 0 | AI8: =IF(SUM(AC8:AH8)>=3,1,IF(SUM(AC8:AH8)<3,0)) -> 0 | AM8: =IF(SUM(AJ8:AL8)>=3,1,IF(SUM(AJ8:AL8)<3,0)) -> 0 | AO8: =IF(AN8>=3,1,0) -> 0 | AQ8: =IF(AP8>=4,1,0) -> 0 | AT8: =(AO8*0.3)+(AQ8*0.3)+(AR8*0.2)+(AS8*0.2) -> 0 | AV8: 0 | AW8: =+(AU8*0.6)+(AV8*0.4) -> 0 | BC8: =((M8*0.1)+(T8*0.05)+(V8*0.2)+(Y7*0.2)+(AB8*0.1)+(AI8*0.05)+(AM8*0.15)+(AT8*0.05)+(AW8*0.1)*100) -> 0
A9: SRN | C9: 5- San Marcos | D9: MAG | E9: mas de 10 años | G9: =IF(F9>=4,1,IF(F9<4,0)) -> 0 | J9: =IF(I9>=0.5,1,0) -> 0 | L9: =IF(K9>=2,1,IF(K9<2,0)) -> 0 | M9: =SUM(G9*0.2+H9*0.3+J9*0.2+L9*0.3) -> 0 | T9: =IF((N9+O9+P9+Q9+S9)>=2,1,IF((N9+O9+P9+Q9+S9)<2,0)) -> 0 | V9: =IF(U9>=2,1,IF(U9<2,0)) -> 0 | Y9: =IF((W9+X9)=2,1,IF((W9+X9)<2,0)) -> 0 | AB9: =Z9*AA9 -> 0 | AI9: =IF(SUM(AC9:AH9)>=3,1,IF(SUM(AC9:AH9)<3,0)) -> 0 | AM9: =IF(SUM(AJ9:AL9)>=3,1,IF(SUM(AJ9:AL9)<3,0)) -> 0 | AO9: =IF(AN9>=3,1,0) -> 0 | AQ9: =IF(AP9>=4,1,0) -> 0 | AT9: =(AO9*0.3)+(AQ9*0.3)+(AR9*0.2)+(AS9*0.2) -> 0 | AU9: 0 | AV9: 0 | AW9: =+(AU9*0.6)+(AV9*0.4) -> 0 | BC9: =((M9*0.1)+(T9*0.05)+(V9*0.2)+(Y8*0.2)+(AB9*0.1)+(AI9*0.05)+(AM9*0.15)+(AT9*0.05)+(AW9*0.1)*100) -> 0
A10: SRN | C10: 6- Los Arados | D10: MABE | E10: 0 - 5 años | G10: =IF(F10>=4,1,IF(F10<4,0)) -> 0 | J10: =IF(I10>=0.5,1,0) -> 0 | L10: =IF(K10>=2,1,IF(K10<2,0)) -> 0 | M10: =SUM(G10*0.2+H10*0.3+J10*0.2+L10*0.3) -> 0 | T10: =IF((N10+O10+P10+Q10+S10)>=2,1,IF((N10+O10+P10+Q10+S10)<2,0)) -> 0 | V10: =IF(U10>=2,1,IF(U10<2,0)) -> 0 | Y10: =IF((W10+X10)=2,1,IF((W10+X10)<2,0)) -> 0 | AB10: =Z10*AA10 -> 0 | AI10: =IF(SUM(AC10:AH10)>=3,1,IF(SUM(AC10:AH10)<3,0)) -> 0 | AM10: =IF(SUM(AJ10:AL10)>=3,1,IF(SUM(AJ10:AL10)<3,0)) -> 0 | AO10: =IF(AN10>=3,1,0) -> 0 | AQ10: =IF(AP10>=4,1,0) -> 0 | AT10: =(AO10*0.3)+(AQ10*0.3)+(AR10*0.2)+(AS10*0.2) -> 0 | AU10: 0 | AV10: 0 | AW10: =+(AU10*0.6)+(AV10*0.4) -> 0 | AX10: =((M10*0.15)+(T10*0.05)+(V10*0.15)+(Y10*0.15)+(AB10*0.15)+(AI10*0.05)+(AM10*0.1)+(AT10*0.1)+(AW10*0.1)*100) -> 0
A11: SRN | C11: 7- Lomas de Sacacli | D11: MABE | E11: 0 - 5 años | G11: =IF(F11>=4,1,IF(F11<4,0)) -> 0 | J11: =IF(I11>=0.5,1,0) -> 0 | L11: =IF(K11>=2,1,IF(K11<2,0)) -> 0 | M11: =SUM(G11*0.2+H11*0.3+J11*0.2+L11*0.3) -> 0 | T11: =IF((N11+O11+P11+Q11+S11)>=2,1,IF((N11+O11+P11+Q11+S11)<2,0)) -> 0 | V11: =IF(U11>=2,1,IF(U11<2,0)) -> 0 | Y11: =IF((W11+X11)=2,1,IF((W11+X11)<2,0)) -> 0 | AB11: =Z11*AA11 -> 0 | AI11: =IF(SUM(AC11:AH11)>=3,1,IF(SUM(AC11:AH11)<3,0)) -> 0 | AM11: =IF(SUM(AJ11:AL11)>=3,1,IF(SUM(AJ11:AL11)<3,0)) -> 0 | AO11: =IF(AN11>=3,1,0) -> 0 | AQ11: =IF(AP11>=4,1,0) -> 0 | AT11: =(AO11*0.3)+(AQ11*0.3)+(AR11*0.2)+(AS11*0.2) -> 0 | AU11: 0 | AV11: 0 | AW11: =+(AU11*0.6)+(AV11*0.4) -> 0 | AX11: =((M11*0.15)+(T11*0.05)+(V11*0.15)+(Y11*0.15)+(AB11*0.15)+(AI11*0.05)+(AM11*0.1)+(AT11*0.1)+(AW11*0.1)*100) -> 0
A12: SRN | C12: 8- Sacacli | D12: MABE | E12: 5 - 10 años | G12: =IF(F12>=4,1,IF(F12<4,0)) -> 0 | J12: =IF(I12>=0.5,1,0) -> 0 | L12: =IF(K12>=2,1,IF(K12<2,0)) -> 0 | M12: =SUM(G12*0.2+H12*0.3+J12*0.2+L12*0.3) -> 0 | T12: =IF((N12+O12+P12+Q12+S12)>=2,1,IF((N12+O12+P12+Q12+S12)<2,0)) -> 0 | V12: =IF(U12>=2,1,IF(U12<2,0)) -> 0 | Y12: =IF((W12+X12)=2,1,IF((W12+X12)<2,0)) -> 0 | AB12: =Z12*AA12 -> 0 | AI12: =IF(SUM(AC12:AH12)>=3,1,IF(SUM(AC12:AH12)<3,0)) -> 0 | AM12: =IF(SUM(AJ12:AL12)>=3,1,IF(SUM(AJ12:AL12)<3,0)) -> 0 | AO12: =IF(AN12>=3,1,0) -> 0 | AQ12: =IF(AP12>=4,1,0) -> 0 | AT12: =(AO12*0.3)+(AQ12*0.3)+(AR12*0.2)+(AS12*0.2) -> 0 | AU12: 0 | AV12: 0 | AW12: =+(AU12*0.6)+(AV12*0.4) -> 0 | AY12: =((M12*0.1)+(T12*0.05)+(V12*0.15)+(Y12*0.2)+(AB12*0.2)+(AI12*0.05)+(AM12*0.1)+(AT12*0.05)+(AW12*0.1)*100) -> 0
A13: SRN | C13: 9- Estación Cerro Grande | E13: No existe SAP | G13: =IF(F13>=4,1,IF(F13<4,0)) -> 0 | J13: =IF(I13>=0.5,1,0) -> 0 | L13: =IF(K13>=2,1,IF(K13<2,0)) -> 0 | M13: =SUM(G13*0.2+H13*0.3+J13*0.2+L13*0.3) -> 0 | T13: =IF((N13+O13+P13+Q13+S13)>=2,1,IF((N13+O13+P13+Q13+S13)<2,0)) -> 0 | V13: =IF(U13>=2,1,IF(U13<2,0)) -> 0 | Y13: =IF((W13+X13)=2,1,IF((W13+X13)<2,0)) -> 0 | AB13: =Z13*AA13 -> 0 | AI13: =IF(SUM(AC13:AH13)>=3,1,IF(SUM(AC13:AH13)<3,0)) -> 0 | AM13: =IF(SUM(AJ13:AL13)>=3,1,IF(SUM(AJ13:AL13)<3,0)) -> 0 | AO13: =IF(AN13>=3,1,0) -> 0 | AQ13: =IF(AP13>=4,1,0) -> 0 | AT13: =(AO13*0.3)+(AQ13*0.3)+(AR13*0.2)+(AS13*0.2) -> 0 | AU13: 0 | AV13: 0 | AW13: =+(AU13*0.6)+(AV13*0.4) -> 0
A14: LC | C14: 10- Valerio | D14: MABE | E14: 5- 10 años | G14: =IF(F14>=4,1,IF(F14<4,0)) -> 0 | J14: =IF(I14>=0.5,1,0) -> 0 | L14: =IF(K14>=2,1,IF(K14<2,0)) -> 0 | M14: =SUM(G14*0.2+H14*0.3+J14*0.2+L14*0.3) -> 0 | T14: =IF((N14+O14+P14+Q14+S14)>=2,1,IF((N14+O14+P14+Q14+S14)<2,0)) -> 0 | V14: =IF(U14>=2,1,IF(U14<2,0)) -> 0 | Y14: =IF((W14+X14)=2,1,IF((W14+X14)<2,0)) -> 0 | AB14: =Z14*AA14 -> 0 | AI14: =IF(SUM(AC14:AH14)>=3,1,IF(SUM(AC14:AH14)<3,0)) -> 0 | AM14: =IF(SUM(AJ14:AL14)>=3,1,IF(SUM(AJ14:AL14)<3,0)) -> 0 | AO14: =IF(AN14>=3,1,0) -> 0 | AQ14: =IF(AP14>=4,1,0) -> 0 | AT14: =(AO14*0.3)+(AQ14*0.3)+(AR14*0.2)+(AS14*0.2) -> 0 | AU14: 0 | AV14: 0 | AW14: =+(AU14*0.6)+(AV14*0.4) -> 0 | AY14: =((M14*0.1)+(T14*0.05)+(V14*0.15)+(Y14*0.2)+(AB14*0.2)+(AI14*0.05)+(AM14*0.1)+(AT14*0.05)+(AW14*0.1)*100) -> 0
A15: LC | C15: 11- Yupali | D15: MABE | E15: 5- 10 años | G15: =IF(F15>=4,1,IF(F15<4,0)) -> 0 | J15: =IF(I15>=0.5,1,0) -> 0 | L15: =IF(K15>=2,1,IF(K15<2,0)) -> 0 | M15: =SUM(G15*0.2+H15*0.3+J15*0.2+L15*0.3) -> 0 | T15: =IF((N15+O15+P15+Q15+S15)>=2,1,IF((N15+O15+P15+Q15+S15)<2,0)) -> 0 | V15: =IF(U15>=2,1,IF(U15<2,0)) -> 0 | Y15: =IF((W15+X15)=2,1,IF((W15+X15)<2,0)) -> 0 | AB15: =Z15*AA15 -> 0 | AI15: =IF(SUM(AC15:AH15)>=3,1,IF(SUM(AC15:AH15)<3,0)) -> 0 | AM15: =IF(SUM(AJ15:AL15)>=3,1,IF(SUM(AJ15:AL15)<3,0)) -> 0 | AO15: =IF(AN15>=3,1,0) -> 0 | AQ15: =IF(AP15>=4,1,0) -> 0 | AT15: =(AO15*0.3)+(AQ15*0.3)+(AR15*0.2)+(AS15*0.2) -> 0 | AU15: 0 | AV15: 0 | AW15: =+(AU15*0.6)+(AV15*0.4) -> 0 | AY15: =((M15*0.1)+(T15*0.05)+(V15*0.15)+(Y15*0.2)+(AB15*0.2)+(AI15*0.05)+(AM15*0.1)+(AT15*0.05)+(AW15*0.1)*100) -> 0
A16: LC | C16: 12- Gracalcan | D16: MAG | E16: 5- 10 años | G16: =IF(F16>=4,1,IF(F16<4,0)) -> 0 | J16: =IF(I16>=0.5,1,0) -> 0 | L16: =IF(K16>=2,1,IF(K16<2,0)) -> 0 | M16: =SUM(G16*0.2+H16*0.3+J16*0.2+L16*0.3) -> 0 | T16: =IF((N16+O16+P16+Q16+S16)>=2,1,IF((N16+O16+P16+Q16+S16)<2,0)) -> 0 | V16: =IF(U16>=2,1,IF(U16<2,0)) -> 0 | Y16: =IF((W16+X16)=2,1,IF((W16+X16)<2,0)) -> 0 | AB16: =Z16*AA16 -> 0 | AI16: =IF(SUM(AC16:AH16)>=3,1,IF(SUM(AC16:AH16)<3,0)) -> 0 | AM16: =IF(SUM(AJ16:AL16)>=3,1,IF(SUM(AJ16:AL16)<3,0)) -> 0 | AO16: =IF(AN16>=3,1,0) -> 0 | AQ16: =IF(AP16>=4,1,0) -> 0 | AT16: =(AO16*0.3)+(AQ16*0.3)+(AR16*0.2)+(AS16*0.2) -> 0 | AU16: 0 | AV16: 0 | AW16: =+(AU16*0.6)+(AV16*0.4) -> 0 | BB16: =((M16*0.15)+(T16*0.05)+(V16*0.15)+(Y16*0.15)+(AB16*0.15)+(AI16*0.1)+(AM16*0.1)+(AT16*0.05)+(AW16*0.1)*100) -> 0
A17: LC | C17: 13- Agua Fria | D17: MAG | E17: 5- 10 años | G17: =IF(F17>=4,1,IF(F17<4,0)) -> 0 | J17: =IF(I17>=0.5,1,0) -> 0 | L17: =IF(K17>=2,1,IF(K17<2,0)) -> 0 | M17: =SUM(G17*0.2+H17*0.3+J17*0.2+L17*0.3) -> 0 | T17: =IF((N17+O17+P17+Q17+S17)>=2,1,IF((N17+O17+P17+Q17+S17)<2,0)) -> 0 | V17: =IF(U17>=2,1,IF(U17<2,0)) -> 0 | Y17: =IF((W17+X17)=2,1,IF((W17+X17)<2,0)) -> 0 | AB17: =Z17*AA17 -> 0 | AI17: =IF(SUM(AC17:AH17)>=3,1,IF(SUM(AC17:AH17)<3,0)) -> 0 | AM17: =IF(SUM(AJ17:AL17)>=3,1,IF(SUM(AJ17:AL17)<3,0)) -> 0 | AO17: =IF(AN17>=3,1,0) -> 0 | AQ17: =IF(AP17>=4,1,0) -> 0 | AT17: =(AO17*0.3)+(AQ17*0.3)+(AR17*0.2)+(AS17*0.2) -> 0 | AU17: 0 | AV17: 0 | AW17: =+(AU17*0.6)+(AV17*0.4) -> 0 | BB17: =((M17*0.15)+(T17*0.05)+(V17*0.15)+(Y17*0.15)+(AB17*0.15)+(AI17*0.1)+(AM17*0.1)+(AT17*0.05)+(AW17*0.1)*100) -> 0
A18: LC | C18: 14- Zapote Oriental | D18: MABE | E18: 0 - 5 años | G18: =IF(F18>=4,1,IF(F18<4,0)) -> 0 | J18: =IF(I18>=0.5,1,0) -> 0 | L18: =IF(K18>=2,1,IF(K18<2,0)) -> 0 | M18: =SUM(G18*0.2+H18*0.3+J18*0.2+L18*0.3) -> 0 | T18: =IF((N18+O18+P18+Q18+S18)>=2,1,IF((N18+O18+P18+Q18+S18)<2,0)) -> 0 | V18: =IF(U18>=2,1,IF(U18<2,0)) -> 0 | Y18: =IF((W18+X18)=2,1,IF((W18+X18)<2,0)) -> 0 | AB18: =Z18*AA18 -> 0 | AI18: =IF(SUM(AC18:AH18)>=3,1,IF(SUM(AC18:AH18)<3,0)) -> 0 | AM18: =IF(SUM(AJ18:AL18)>=3,1,IF(SUM(AJ18:AL18)<3,0)) -> 0 | AO18: =IF(AN18>=3,1,0) -> 0 | AQ18: =IF(AP18>=4,1,0) -> 0 | AT18: =(AO18*0.3)+(AQ18*0.3)+(AR18*0.2)+(AS18*0.2) -> 0 | AU18: 0 | AV18: 0 | AW18: =+(AU18*0.6)+(AV18*0.4) -> 0 | AX18: =((M18*0.15)+(T18*0.05)+(V18*0.15)+(Y18*0.15)+(AB18*0.15)+(AI18*0.05)+(AM18*0.1)+(AT18*0.1)+(AW18*0.1)*100) -> 0
A19: LC | C19: 15- Santiago del Coyolito | D19: MABE | E19: 5 - 10 años | G19: =IF(F19>=4,1,IF(F19<4,0)) -> 0 | J19: =IF(I19>=0.5,1,0) -> 0 | L19: =IF(K19>=2,1,IF(K19<2,0)) -> 0 | M19: =SUM(G19*0.2+H19*0.3+J19*0.2+L19*0.3) -> 0 | T19: =IF((N19+O19+P19+Q19+S19)>=2,1,IF((N19+O19+P19+Q19+S19)<2,0)) -> 0 | V19: =IF(U19>=2,1,IF(U19<2,0)) -> 0 | Y19: =IF((W19+X19)=2,1,IF((W19+X19)<2,0)) -> 0 | AB19: =Z19*AA19 -> 0 | AI19: =IF(SUM(AC19:AH19)>=3,1,IF(SUM(AC19:AH19)<3,0)) -> 0 | AM19: =IF(SUM(AJ19:AL19)>=3,1,IF(SUM(AJ19:AL19)<3,0)) -> 0 | AO19: =IF(AN19>=3,1,0) -> 0 | AQ19: =IF(AP19>=4,1,0) -> 0 | AT19: =(AO19*0.3)+(AQ19*0.3)+(AR19*0.2)+(AS19*0.2) -> 0 | AU19: 0 | AV19: 0 | AW19: =+(AU19*0.6)+(AV19*0.4) -> 0 | AY19: =((M19*0.1)+(T19*0.05)+(V19*0.15)+(Y19*0.2)+(AB19*0.2)+(AI19*0.05)+(AM19*0.1)+(AT19*0.05)+(AW19*0.1)*100) -> 0
A20: LC | C20: 16- Las Quebradas | E20: No existe SAP | G20: =IF(F20>=4,1,IF(F20<4,0)) -> 0 | J20: =IF(I20>=0.5,1,0) -> 0 | L20: =IF(K20>=2,1,IF(K20<2,0)) -> 0 | M20: =SUM(G20*0.2+H20*0.3+J20*0.2+L20*0.3) -> 0 | T20: =IF((N20+O20+P20+Q20+S20)>=2,1,IF((N20+O20+P20+Q20+S20)<2,0)) -> 0 | V20: =IF(U20>=2,1,IF(U20<2,0)) -> 0 | Y20: =IF((W20+X20)=2,1,IF((W20+X20)<2,0)) -> 0 | AB20: =Z20*AA20 -> 0 | AI20: =IF(SUM(AC20:AH20)>=3,1,IF(SUM(AC20:AH20)<3,0)) -> 0 | AM20: =IF(SUM(AJ20:AL20)>=3,1,IF(SUM(AJ20:AL20)<3,0)) -> 0 | AO20: =IF(AN20>=3,1,0) -> 0 | AQ20: =IF(AP20>=4,1,0) -> 0 | AT20: =(AO20*0.3)+(AQ20*0.3)+(AR20*0.2)+(AS20*0.2) -> 0 | AU20: 0 | AV20: 0 | AW20: =+(AU20*0.6)+(AV20*0.4) -> 0
A21: SSY | C21: 17- La Naranjita | D21: MAG | E21: 0 - 5 años | G21: =IF(F21>=4,1,IF(F21<4,0)) -> 0 | J21: =IF(I21>=0.5,1,0) -> 0 | L21: =IF(K21>=2,1,IF(K21<2,0)) -> 0 | M21: =SUM(G21*0.2+H21*0.3+J21*0.2+L21*0.3) -> 0 | T21: =IF((N21+O21+P21+Q21+S21)>=2,1,IF((N21+O21+P21+Q21+S21)<2,0)) -> 0 | V21: =IF(U21>=2,1,IF(U21<2,0)) -> 0 | Y21: =IF((W21+X21)=2,1,IF((W21+X21)<2,0)) -> 0 | AB21: =Z21*AA21 -> 0 | AI21: =IF(SUM(AC21:AH21)>=3,1,IF(SUM(AC21:AH21)<3,0)) -> 0 | AM21: =IF(SUM(AJ21:AL21)>=3,1,IF(SUM(AJ21:AL21)<3,0)) -> 0 | AO21: =IF(AN21>=3,1,0) -> 0 | AQ21: =IF(AP21>=4,1,0) -> 0 | AT21: =(AO21*0.3)+(AQ21*0.3)+(AR21*0.2)+(AS21*0.2) -> 0 | AU21: 0 | AV21: 0 | AW21: =+(AU21*0.6)+(AV21*0.4) -> 0 | BA21: =((M21*0.15)+(T21*0.05)+(V21*0.15)+(Y21*0.15)+(AB21*0.15)+(AI21*0.05)+(AM21*0.1)+(AT21*0.1)+(AW21*0.1)*100) -> 0
A22: SSY | C22: 18- Los Prendedizos | D22: MAG | E22: 5 -10 años | G22: =IF(F22>=4,1,IF(F22<4,0)) -> 0 | J22: =IF(I22>=0.5,1,0) -> 0 | L22: =IF(K22>=2,1,IF(K22<2,0)) -> 0 | M22: =SUM(G22*0.2+H22*0.3+J22*0.2+L22*0.3) -> 0 | T22: =IF((N22+O22+P22+Q22+S22)>=2,1,IF((N22+O22+P22+Q22+S22)<2,0)) -> 0 | V22: =IF(U22>=2,1,IF(U22<2,0)) -> 0 | Y22: =IF((W22+X22)=2,1,IF((W22+X22)<2,0)) -> 0 | AB22: =Z22*AA22 -> 0 | AI22: =IF(SUM(AC22:AH22)>=3,1,IF(SUM(AC22:AH22)<3,0)) -> 0 | AM22: =IF(SUM(AJ22:AL22)>=3,1,IF(SUM(AJ22:AL22)<3,0)) -> 0 | AO22: =IF(AN22>=3,1,0) -> 0 | AQ22: =IF(AP22>=4,1,0) -> 0 | AT22: =(AO22*0.3)+(AQ22*0.3)+(AR22*0.2)+(AS22*0.2) -> 0 | AU22: 0 | AV22: 0 | AW22: =+(AU22*0.6)+(AV22*0.4) -> 0 | BB22: =((M22*0.15)+(T22*0.05)+(V22*0.15)+(Y22*0.15)+(AB22*0.15)+(AI22*0.1)+(AM22*0.1)+(AT22*0.05)+(AW22*0.1)*100) -> 0
A23: SSY | C23: 19- Las Trozas | D23: MAG | E23: 5 - 10 años | G23: =IF(F23>=4,1,IF(F23<4,0)) -> 0 | J23: =IF(I23>=0.5,1,0) -> 0 | L23: =IF(K23>=2,1,IF(K23<2,0)) -> 0 | M23: =SUM(G23*0.2+H23*0.3+J23*0.2+L23*0.3) -> 0 | T23: =IF((N23+O23+P23+Q23+S23)>=2,1,IF((N23+O23+P23+Q23+S23)<2,0)) -> 0 | V23: =IF(U23>=2,1,IF(U23<2,0)) -> 0 | Y23: =IF((W23+X23)=2,1,IF((W23+X23)<2,0)) -> 0 | AB23: =Z23*AA23 -> 0 | AI23: =IF(SUM(AC23:AH23)>=3,1,IF(SUM(AC23:AH23)<3,0)) -> 0 | AM23: =IF(SUM(AJ23:AL23)>=3,1,IF(SUM(AJ23:AL23)<3,0)) -> 0 | AO23: =IF(AN23>=3,1,0) -> 0 | AQ23: =IF(AP23>=4,1,0) -> 0 | AT23: =(AO23*0.3)+(AQ23*0.3)+(AR23*0.2)+(AS23*0.2) -> 0 | AU23: 0 | AV23: 0 | AW23: =+(AU23*0.6)+(AV23*0.4) -> 0 | BB23: =((M23*0.15)+(T23*0.05)+(V23*0.15)+(Y23*0.15)+(AB23*0.15)+(AI23*0.1)+(AM23*0.1)+(AT23*0.05)+(AW23*0.1)*100) -> 0
A24: SSY | C24: 20- Las Delicias | D24: MAG | E24: 0 - 5 años | G24: =IF(F24>=4,1,IF(F24<4,0)) -> 0 | J24: =IF(I24>=0.5,1,0) -> 0 | L24: =IF(K24>=2,1,IF(K24<2,0)) -> 0 | M24: =SUM(G24*0.2+H24*0.3+J24*0.2+L24*0.3) -> 0 | T24: =IF((N24+O24+P24+Q24+S24)>=2,1,IF((N24+O24+P24+Q24+S24)<2,0)) -> 0 | V24: =IF(U24>=2,1,IF(U24<2,0)) -> 0 | Y24: =IF((W24+X24)=2,1,IF((W24+X24)<2,0)) -> 0 | AB24: =Z24*AA24 -> 0 | AI24: =IF(SUM(AC24:AH24)>=3,1,IF(SUM(AC24:AH24)<3,0)) -> 0 | AM24: =IF(SUM(AJ24:AL24)>=3,1,IF(SUM(AJ24:AL24)<3,0)) -> 0 | AO24: =IF(AN24>=3,1,0) -> 0 | AQ24: =IF(AP24>=4,1,0) -> 0 | AT24: =(AO24*0.3)+(AQ24*0.3)+(AR24*0.2)+(AS24*0.2) -> 0 | AU24: 0 | AV24: 0 | AW24: =+(AU24*0.6)+(AV24*0.4) -> 0 | BA24: =((M24*0.15)+(T24*0.05)+(V24*0.15)+(Y24*0.15)+(AB24*0.15)+(AI24*0.05)+(AM24*0.1)+(AT24*0.1)+(AW24*0.1)*100) -> 0
A25: SSY | C25: 21- El Volcán | D25: MAG | E25: 5 - 10 años | G25: =IF(F25>=4,1,IF(F25<4,0)) -> 0 | J25: =IF(I25>=0.5,1,0) -> 0 | L25: =IF(K25>=2,1,IF(K25<2,0)) -> 0 | M25: =SUM(G25*0.2+H25*0.3+J25*0.2+L25*0.3) -> 0 | T25: =IF((N25+O25+P25+Q25+S25)>=2,1,IF((N25+O25+P25+Q25+S25)<2,0)) -> 0 | V25: =IF(U25>=2,1,IF(U25<2,0)) -> 0 | Y25: =IF((W25+X25)=2,1,IF((W25+X25)<2,0)) -> 0 | AB25: =Z25*AA25 -> 0 | AI25: =IF(SUM(AC25:AH25)>=3,1,IF(SUM(AC25:AH25)<3,0)) -> 0 | AM25: =IF(SUM(AJ25:AL25)>=3,1,IF(SUM(AJ25:AL25)<3,0)) -> 0 | AO25: =IF(AN25>=3,1,0) -> 0 | AQ25: =IF(AP25>=4,1,0) -> 0 | AT25: =(AO25*0.3)+(AQ25*0.3)+(AR25*0.2)+(AS25*0.2) -> 0 | AU25: 0 | AV25: 0 | AW25: =+(AU25*0.6)+(AV25*0.4) -> 0 | BB25: =((M25*0.15)+(T25*0.05)+(V25*0.15)+(Y25*0.15)+(AB25*0.15)+(AI25*0.1)+(AM25*0.1)+(AT25*0.05)+(AW25*0.1)*100) -> 0
A26: SSY | C26: 22- El Regadio | D26: MAG | E26: 0- 5 años | G26: =IF(F26>=4,1,IF(F26<4,0)) -> 0 | J26: =IF(I26>=0.5,1,0) -> 0 | L26: =IF(K26>=2,1,IF(K26<2,0)) -> 0 | M26: =SUM(G26*0.2+H26*0.3+J26*0.2+L26*0.3) -> 0 | T26: =IF((N26+O26+P26+Q26+S26)>=2,1,IF((N26+O26+P26+Q26+S26)<2,0)) -> 0 | V26: =IF(U26>=2,1,IF(U26<2,0)) -> 0 | Y26: =IF((W26+X26)=2,1,IF((W26+X26)<2,0)) -> 0 | AB26: =Z26*AA26 -> 0 | AI26: =IF(SUM(AC26:AH26)>=3,1,IF(SUM(AC26:AH26)<3,0)) -> 0 | AM26: =IF(SUM(AJ26:AL26)>=3,1,IF(SUM(AJ26:AL26)<3,0)) -> 0 | AO26: =IF(AN26>=3,1,0) -> 0 | AQ26: =IF(AP26>=4,1,0) -> 0 | AT26: =(AO26*0.3)+(AQ26*0.3)+(AR26*0.2)+(AS26*0.2) -> 0 | AU26: 0 | AV26: 0 | AW26: =+(AU26*0.6)+(AV26*0.4) -> 0 | BA26: =((M26*0.15)+(T26*0.05)+(V26*0.15)+(Y26*0.15)+(AB26*0.15)+(AI26*0.05)+(AM26*0.1)+(AT26*0.1)+(AW26*0.1)*100) -> 0
A27: SSY | C27: 23- Quebrada Arriba | D27: MAG | E27: 5 - 10 años | G27: =IF(F27>=4,1,IF(F27<4,0)) -> 0 | J27: =IF(I27>=0.5,1,0) -> 0 | L27: =IF(K27>=2,1,IF(K27<2,0)) -> 0 | M27: =SUM(G27*0.2+H27*0.3+J27*0.2+L27*0.3) -> 0 | T27: =IF((N27+O27+P27+Q27+S27)>=2,1,IF((N27+O27+P27+Q27+S27)<2,0)) -> 0 | V27: =IF(U27>=2,1,IF(U27<2,0)) -> 0 | Y27: =IF((W27+X27)=2,1,IF((W27+X27)<2,0)) -> 0 | AB27: =Z27*AA27 -> 0 | AI27: =IF(SUM(AC27:AH27)>=3,1,IF(SUM(AC27:AH27)<3,0)) -> 0 | AM27: =IF(SUM(AJ27:AL27)>=3,1,IF(SUM(AJ27:AL27)<3,0)) -> 0 | AO27: =IF(AN27>=3,1,0) -> 0 | AQ27: =IF(AP27>=4,1,0) -> 0 | AT27: =(AO27*0.3)+(AQ27*0.3)+(AR27*0.2)+(AS27*0.2) -> 0 | AU27: 0 | AV27: 0 | AW27: =+(AU27*0.6)+(AV27*0.4) -> 0 | BB27: =((M27*0.15)+(T27*0.05)+(V27*0.15)+(Y27*0.15)+(AB27*0.15)+(AI27*0.1)+(AM27*0.1)+(AT27*0.05)+(AW27*0.1)*100) -> 0
A28: SSY | C28: 24- La Garita | D28: MAG | E28: 5 - 10 años | G28: =IF(F28>=4,1,IF(F28<4,0)) -> 0 | J28: =IF(I28>=0.5,1,0) -> 0 | L28: =IF(K28>=2,1,IF(K28<2,0)) -> 0 | M28: =SUM(G28*0.2+H28*0.3+J28*0.2+L28*0.3) -> 0 | T28: =IF((N28+O28+P28+Q28+S28)>=2,1,IF((N28+O28+P28+Q28+S28)<2,0)) -> 0 | V28: =IF(U28>=2,1,IF(U28<2,0)) -> 0 | Y28: =IF((W28+X28)=2,1,IF((W28+X28)<2,0)) -> 0 | AB28: =Z28*AA28 -> 0 | AI28: =IF(SUM(AC28:AH28)>=3,1,IF(SUM(AC28:AH28)<3,0)) -> 0 | AM28: =IF(SUM(AJ28:AL28)>=3,1,IF(SUM(AJ28:AL28)<3,0)) -> 0 | AO28: =IF(AN28>=3,1,0) -> 0 | AQ28: =IF(AP28>=4,1,0) -> 0 | AT28: =(AO28*0.3)+(AQ28*0.3)+(AR28*0.2)+(AS28*0.2) -> 0 | AU28: 0 | AV28: 0 | AW28: =+(AU28*0.6)+(AV28*0.4) -> 0 | BB28: =((M28*0.15)+(T28*0.05)+(V28*0.15)+(Y28*0.15)+(AB28*0.15)+(AI28*0.1)+(AM28*0.1)+(AT28*0.05)+(AW28*0.1)*100) -> 0
A29: SSY | C29: 25- Cayancimil | D29: MAG | E29: 5 - 10 años | G29: =IF(F29>=4,1,IF(F29<4,0)) -> 0 | J29: =IF(I29>=0.5,1,0) -> 0 | L29: =IF(K29>=2,1,IF(K29<2,0)) -> 0 | M29: =SUM(G29*0.2+H29*0.3+J29*0.2+L29*0.3) -> 0 | T29: =IF((N29+O29+P29+Q29+S29)>=2,1,IF((N29+O29+P29+Q29+S29)<2,0)) -> 0 | V29: =IF(U29>=2,1,IF(U29<2,0)) -> 0 | Y29: =IF((W29+X29)=2,1,IF((W29+X29)<2,0)) -> 0 | AB29: =Z29*AA29 -> 0 | AI29: =IF(SUM(AC29:AH29)>=3,1,IF(SUM(AC29:AH29)<3,0)) -> 0 | AM29: =IF(SUM(AJ29:AL29)>=3,1,IF(SUM(AJ29:AL29)<3,0)) -> 0 | AO29: =IF(AN29>=3,1,0) -> 0 | AQ29: =IF(AP29>=4,1,0) -> 0 | AT29: =(AO29*0.3)+(AQ29*0.3)+(AR29*0.2)+(AS29*0.2) -> 0 | AU29: 0 | AV29: 0 | AW29: =+(AU29*0.6)+(AV29*0.4) -> 0 | BB29: =((M29*0.15)+(T29*0.05)+(V29*0.15)+(Y29*0.15)+(AB29*0.15)+(AI29*0.1)+(AM29*0.1)+(AT29*0.05)+(AW29*0.1)*100) -> 0
A30: SSY | C30: 26- El Barro | D30: MAG | E30: 0 - 5 años | G30: =IF(F30>=4,1,IF(F30<4,0)) -> 0 | J30: =IF(I30>=0.5,1,0) -> 0 | L30: =IF(K30>=2,1,IF(K30<2,0)) -> 0 | M30: =SUM(G30*0.2+H30*0.3+J30*0.2+L30*0.3) -> 0 | T30: =IF((N30+O30+P30+Q30+S30)>=2,1,IF((N30+O30+P30+Q30+S30)<2,0)) -> 0 | V30: =IF(U30>=2,1,IF(U30<2,0)) -> 0 | Y30: =IF((W30+X30)=2,1,IF((W30+X30)<2,0)) -> 0 | AB30: =Z30*AA30 -> 0 | AI30: =IF(SUM(AC30:AH30)>=3,1,IF(SUM(AC30:AH30)<3,0)) -> 0 | AM30: =IF(SUM(AJ30:AL30)>=3,1,IF(SUM(AJ30:AL30)<3,0)) -> 0 | AO30: =IF(AN30>=3,1,0) -> 0 | AQ30: =IF(AP30>=4,1,0) -> 0 | AT30: =(AO30*0.3)+(AQ30*0.3)+(AR30*0.2)+(AS30*0.2) -> 0 | AU30: 0 | AV30: 0 | AW30: =+(AU30*0.6)+(AV30*0.4) -> 0 | BA30: =((M30*0.15)+(T30*0.05)+(V30*0.15)+(Y30*0.15)+(AB30*0.15)+(AI30*0.05)+(AM30*0.1)+(AT30*0.1)+(AW30*0.1)*100) -> 0

Sheet ytyy
C2: TIPO DE SISTEMA: MAG
A3: Municipio | B3: COMUNIDAD | C3: 1)CAPTACION | H3: 2)TANQUE DE ALMACENAMIENTO | P3: 3) CLORINADOR | R3: 4) OTROS
C4: MAG1 | D4: MAG2 | E4: MAG3 | F4: MAG4 | G4: H1 | H4: MAG5 | I4: MAG6 | J4: MAG7 | K4: MAG8 | L4: MAG9 | M4: MAG10 | N4: MAG11 | O4: H2 | P4: MAG12 | Q4: H3 | R4: MAG13 | S4: H4 | T4: Entrevistado por: | U4: Fecha de la Entrevista
C5: ¿Está cerca la obra de captación, a la primera casa? | D5: ¿La cerca de la obra de captación está en buen estado? | E5: No se observan focos de contaminación (restos de envases de pesticidas, basura, heces…) alrededor de la fuente de agua? | F5: ¿No Tiene grietas la obra de captación? | H5: Está cercado el tanque de almacenamiento? | I5: La cerca del tanque está en buen estado? | J5: No tiene grietas el tanque de almacenamiento? | K5: No Tiene fugas el tanque de almacenamiento? | L5: No Rebosa el tanque de almacenamiento? | M5: Están las válvulas del tanque en buen estado? | N5: Está la tapa de inspección en buen estado? | P5: Está funcionando el sistema de cloración? | R5: Durante el recorrido, hay fugas visibles en el sistema?
A6: SRN | B6: 1- El Diamante. | C6: 1 | D6: 1 | E6: 0 | F6: 0 | G6: =+SUM(C6:F6) -> 2 | H6: 1 | I6: 1 | J6: 1 | K6: 1 | L6: 0 | M6: 1 | N6: 1 | O6: =+SUM(H6:N6) -> 6 | P6: 0 | Q6: =+P6 -> 0 | R6: 0 | S6: =+R6 -> 0 | T6: Nohemi Mercado | U6: 40952
A7: SRN | B7: 2- La Breiera | C7: 0 | D7: 0 | E7: 1 | F7: 0 | G7: =+SUM(C7:F7) -> 1 | H7: 0 | I7: 0 | J7: 1 | K7: 0 | L7: 1 | M7: 0 | N7: 1 | O7: =+SUM(H7:N7) -> 3 | P7: 0 | Q7: =+P7 -> 0 | R7: 0 | S7: =+R7 -> 0 | T7: Nohemi Mercado | U7: 40953
A8: SRN | B8: 3- Valle de Suni | G8: =+SUM(C8:F8) -> 0 | O8: =+SUM(H8:N8) -> 0 | Q8: =+P8 -> 0 | S8: =+R8 -> 0
A9: SRN | B9: 4- El Espino | G9: =+SUM(C9:F9) -> 0 | O9: =+SUM(H9:N9) -> 0 | Q9: =+P9 -> 0 | S9: =+R9 -> 0
A10: SRN | B10: 5- San Marcos | G10: =+SUM(C10:F10) -> 0 | O10: =+SUM(H10:N10) -> 0 | Q10: =+P10 -> 0 | S10: =+R10 -> 0
A11: SRN | B11: 6- Los Arados | G11: =+SUM(C11:F11) -> 0 | O11: =+SUM(H11:N11) -> 0 | Q11: =+P11 -> 0 | S11: =+R11 -> 0
A12: SRN | B12: 7- Lomas de Sacacli | G12: =+SUM(C12:F12) -> 0 | O12: =+SUM(H12:N12) -> 0 | Q12: =+P12 -> 0 | S12: =+R12 -> 0
A13: SRN | B13: 8- Sacacli | G13: =+SUM(C13:F13) -> 0 | O13: =+SUM(H13:N13) -> 0 | Q13: =+P13 -> 0 | S13: =+R13 -> 0
A14: SRN | B14: 9- Estación Cerro Grande | G14: =+SUM(C14:F14) -> 0 | O14: =+SUM(H14:N14) -> 0 | Q14: =+P14 -> 0 | S14: =+R14 -> 0
A15: LC | B15: 10- Valerio | G15: =+SUM(C15:F15) -> 0 | O15: =+SUM(H15:N15) -> 0 | Q15: =+P15 -> 0 | S15: =+R15 -> 0
A16: LC | B16: 11- Yupali | G16: =+SUM(C16:F16) -> 0 | O16: =+SUM(H16:N16) -> 0 | Q16: =+P16 -> 0 | S16: =+R16 -> 0
A17: LC | B17: 12- Gracalcan | C17: 0 | D17: 1 | E17: 1 | F17: 1 | G17: =+SUM(C17:F17) -> 3 | H17: 1 | I17: 0 | J17: 1 | K17: 1 | L17: 1 | M17: 0 | N17: 1 | O17: =+SUM(H17:N17) -> 5 | P17: 1 | Q17: =+P17 -> 1 | R17: 0 | S17: =+R17 -> 0 | T17: Arlen Zeledón | U17: 40955
A18: LC | B18: 13- Agua Fria | C18: 0 | D18: 1 | E18: 1 | F18: 1 | G18: =+SUM(C18:F18) -> 3 | H18: 0 | I18: 1 | J18: 1 | K18: 1 | L18: 0 | M18: 0 | N18: 1 | O18: =+SUM(H18:N18) -> 4 | P18: 1 | Q18: =+P18 -> 1 | R18: 0 | S18: =+R18 -> 0 | T18: Arlen Zeledón | U18: 40959
A19: LC | B19: 14- Zapote Oriental | G19: =+SUM(C19:F19) -> 0 | O19: =+SUM(H19:N19) -> 0 | Q19: =+P19 -> 0 | S19: =+R19 -> 0
A20: LC | B20: 15- Santiago del Coyolito | G20: =+SUM(C20:F20) -> 0 | O20: =+SUM(H20:N20) -> 0 | Q20: =+P20 -> 0 | S20: =+R20 -> 0
A21: LC | B21: 16- Las Quebradas | G21: =+SUM(C21:F21) -> 0 | O21: =+SUM(H21:N21) -> 0 | Q21: =+P21 -> 0 | S21: =+R21 -> 0
A22: SSY | B22: 17- La Naranjita | G22: =+SUM(C22:F22) -> 0 | O22: =+SUM(H22:N22) -> 0 | Q22: =+P22 -> 0 | S22: =+R22 -> 0
A23: SSY | B23: 18- Los Prendedizos | G23: =+SUM(C23:F23) -> 0 | O23: =+SUM(H23:N23) -> 0 | Q23: =+P23 -> 0 | S23: =+R23 -> 0
A24: SSY | B24: 19- Las Trozas | G24: =+SUM(C24:F24) -> 0 | O24: =+SUM(H24:N24) -> 0 | Q24: =+P24 -> 0 | S24: =+R24 -> 0
A25: SSY | B25: 20- Las Delicias | G25: =+SUM(C25:F25) -> 0 | O25: =+SUM(H25:N25) -> 0 | Q25: =+P25 -> 0 | S25: =+R25 -> 0
A26: SSY | B26: 21- El Volcán | G26: =+SUM(C26:F26) -> 0 | O26: =+SUM(H26:N26) -> 0 | Q26: =+P26 -> 0 | S26: =+R26 -> 0
A27: SSY | B27: 22- El Regadio | G27: =+SUM(C27:F27) -> 0 | O27: =+SUM(H27:N27) -> 0 | Q27: =+P27 -> 0 | S27: =+R27 -> 0
A28: SSY | B28: 23- Quebrada Arriba | G28: =+SUM(C28:F28) -> 0 | O28: =+SUM(H28:N28) -> 0 | Q28: =+P28 -> 0 | S28: =+R28 -> 0
A29: SSY | B29: 24- La Garita | G29: =+SUM(C29:F29) -> 0 | O29: =+SUM(H29:N29) -> 0 | Q29: =+P29 -> 0 | S29: =+R29 -> 0
A30: SSY | B30: 25- Cayancimil | G30: =+SUM(C30:F30) -> 0 | O30: =+SUM(H30:N30) -> 0 | Q30: =+P30 -> 0 | S30: =+R30 -> 0
A31: SSY | B31: 26- El Barro | G31: =+SUM(C31:F31) -> 0 | O31: =+SUM(H31:N31) -> 0 | Q31: =+P31 -> 0 | S31: =+R31 -> 0

Sheet Est_Conserv_MABE
C4: ESTADO DE CONSERVACION DE LOS SISTEMAS MABE
A5: Municipio | B5: COMUNIDAD | C5: 1) Estación de Bombeo | H5: H1 | I5: 2)Tanque de Almacenamiento | P5: H2 | Q5: 3) Clorinador | R5: H3 | S5: 4) Otros | T5: H4 | U5: Entrevistado por: | V5: Fecha de la Entrevista
C6: MABE1 | D6: MABE 2 | E6: MABE3 | F6: MABE4 | G6: MABE5 | I6: MABE6 | J6: MABE7 | K6: MABE8 | L6: MABE9 | M6: MABE10 | N6: MABE11 | O6: MABE12 | Q6: MABE14 | S6: MABE16
C7: Tiene cerco de protección el predio del pozo | D7: No hay letrinas ubicadas a menos de 20 mts del pozo | E7: Las paredes y el techo de la caseta de bombeo están en buen estado? | F7: La caseta tiene puerta cerrada con llave | G7: Está registrando el macromedidor | I7: Está cercado el tanque de almacenamiento? | J7: La cerca del tanque está en buen estado? | K7: No tiene grietas el tanque de almacenamiento? | L7: No Tiene fugas el tanque de almacenamiento? | M7: No Rebosa el tanque de almacenamiento? | N7: Están las válvulas del tanque en buen estado? | O7: Está la tapa de inspección en buen estado? | Q7: Está funcionando el sistema de cloración? | S7: Durante el recorrido, No hay fugas visibles en el sistema?
A8: SRN | B8: 1- El Diamante. | H8: =+SUM(C8:G8) -> 0 | P8: =+SUM(I8:O8) -> 0 | R8: =+Q8 -> 0 | S8: =+R8 -> 0 | T8: =+S8 -> 0
A9: SRN | B9: 2- La Breiera | H9: =+SUM(C9:G9) -> 0 | P9: =+SUM(I9:O9) -> 0 | R9: =+Q9 -> 0 | S9: =+R9 -> 0 | T9: =+S9 -> 0
A10: SRN | B10: 3- Valle de Suni | H10: =+SUM(C10:G10) -> 0 | P10: =+SUM(I10:O10) -> 0 | R10: =+Q10 -> 0 | S10: =+R10 -> 0 | T10: =+S10 -> 0
A11: SRN | B11: 4- El Espino | H11: =+SUM(C11:G11) -> 0 | P11: =+SUM(I11:O11) -> 0 | R11: =+Q11 -> 0 | S11: =+R11 -> 0 | T11: =+S11 -> 0
A12: SRN | B12: 5- San Marcos | H12: =+SUM(C12:G12) -> 0 | P12: =+SUM(I12:O12) -> 0 | R12: =+Q12 -> 0 | S12: =+R12 -> 0 | T12: =+S12 -> 0
A13: SRN | B13: 6- Los Arados | H13: =+SUM(C13:G13) -> 0 | P13: =+SUM(I13:O13) -> 0 | R13: =+Q13 -> 0 | S13: =+R13 -> 0 | T13: =+S13 -> 0
A14: SRN | B14: 7- Lomas de Sacacli | H14: =+SUM(C14:G14) -> 0 | P14: =+SUM(I14:O14) -> 0 | R14: =+Q14 -> 0 | S14: =+R14 -> 0 | T14: =+S14 -> 0
A15: SRN | B15: 8- Sacacli | H15: =+SUM(C15:G15) -> 0 | P15: =+SUM(I15:O15) -> 0 | R15: =+Q15 -> 0 | S15: =+R15 -> 0 | T15: =+S15 -> 0
A16: SRN | B16: 9- Estación Cerro Grande | H16: =+SUM(C16:G16) -> 0 | P16: =+SUM(I16:O16) -> 0 | R16: =+Q16 -> 0 | S16: =+R16 -> 0 | T16: =+S16 -> 0
A17: LC | B17: 10- Valerio | C17: 1 | D17: 1 | E17: 1 | F17: 1 | G17: 1 | H17: =+SUM(C17:G17) -> 5 | I17: 1 | J17: 1 | K17: 1 | L17: 1 | M17: 1 | N17: 0 | O17: 1 | P17: =+SUM(I17:O17) -> 6 | Q17: 1 | R17: =+Q17 -> 1 | S17: 1 | T17: =+S17 -> 1 | U17: Arlen Zeledón | V17: 40952
A18: LC | B18: 11- Yupali | C18: 1 | D18: 1 | E18: 1 | F18: 1 | G18: 1 | H18: =+SUM(C18:G18) -> 5 | I18: 1 | J18: 1 | K18: 1 | L18: 1 | M18: 1 | N18: 0 | O18: 1 | P18: =+SUM(I18:O18) -> 6 | Q18: 1 | R18: =+Q18 -> 1 | S18: 1 | T18: =+S18 -> 1 | U18: Arlen Zeledón | V18: 40955
A19: LC | B19: 14- Zapote Oriental | H19: =+SUM(C19:G19) -> 0 | P19: =+SUM(I19:O19) -> 0 | R19: =+Q19 -> 0 | S19: =+R19 -> 0 | T19: =+S19 -> 0
A20: LC | B20: 15- Santiago del Coyolito | C20: 1 | D20: 1 | E20: 1 | F20: 1 | G20: 1 | H20: =+SUM(C20:G20) -> 5 | I20: 1 | J20: 1 | K20: 1 | L20: 1 | M20: 0 | N20: 1 | O20: 1 | P20: =+SUM(I20:O20) -> 6 | Q20: 1 | R20: =+Q20 -> 1 | S20: =+R20 -> 1 | T20: =+S20 -> 1 | U20: Arlen Zeledón | V20: 13702/12
A21: LC | B21: 16- Las Quebradas | H21: =+SUM(C21:G21) -> 0 | I21: =+SUM(I8:I20) -> 3 | J21: =+SUM(J8:J20) -> 3 | K21: =+SUM(K8:K20) -> 3 | L21: =+SUM(L8:L20) -> 3 | M21: =+SUM(M8:M20) -> 2 | N21: =+SUM(N8:N20) -> 1 | P21: =+SUM(I21:O21) -> 15 | R21: =+Q21 -> 0 | S21: =+R21 -> 0 | T21: =+S21 -> 0
A22: SSY | B22: 17- La Naranjita | H22: =+SUM(C22:G22) -> 0 | P22: =+SUM(I22:O22) -> 0 | R22: =+Q22 -> 0 | S22: =+R22 -> 0 | T22: =+S22 -> 0
A23: SSY | B23: 18- Los Prendedizos | H23: =+SUM(C23:G23) -> 0 | P23: =+SUM(I23:O23) -> 0 | R23: =+Q23 -> 0 | S23: =+R23 -> 0 | T23: =+S23 -> 0
A24: SSY | B24: 19- Las Trozas | H24: =+SUM(C24:G24) -> 0 | P24: =+SUM(I24:O24) -> 0 | R24: =+Q24 -> 0 | S24: =+R24 -> 0 | T24: =+S24 -> 0
A25: SSY | B25: 20- Las Delicias | H25: =+SUM(C25:G25) -> 0 | P25: =+SUM(I25:O25) -> 0 | R25: =+Q25 -> 0 | S25: =+R25 -> 0 | T25: =+S25 -> 0
A26: SSY | B26: 21- El Volcán | H26: =+SUM(C26:G26) -> 0 | P26: =+SUM(I26:O26) -> 0 | R26: =+Q26 -> 0 | S26: =+R26 -> 0 | T26: =+S26 -> 0
A27: SSY | B27: 22- El Regadio | H27: =+SUM(C27:G27) -> 0 | P27: =+SUM(I27:O27) -> 0 | R27: =+Q27 -> 0 | S27: =+R27 -> 0 | T27: =+S27 -> 0
A28: SSY | B28: 23- Quebrada Arriba | H28: =+SUM(C28:G28) -> 0 | P28: =+SUM(I28:O28) -> 0 | R28: =+Q28 -> 0 | S28: =+R28 -> 0 | T28: =+S28 -> 0
A29: SSY | B29: 24- La Garita | H29: =+SUM(C29:G29) -> 0 | P29: =+SUM(I29:O29) -> 0 | R29: =+Q29 -> 0 | S29: =+R29 -> 0 | T29: =+S29 -> 0
A30: SSY | B30: 25- Cayancimil | H30: =+SUM(C30:G30) -> 0 | P30: =+SUM(I30:O30) -> 0 | R30: =+Q30 -> 0 | S30: =+R30 -> 0 | T30: =+S30 -> 0
A31: SSY | B31: 26- El Barro | H31: =+SUM(C31:G31) -> 0 | P31: =+SUM(I31:O31) -> 0 | R31: =+Q31 -> 0 | S31: =+R31 -> 0 | T31: =+S31 -> 0

Sheet Tabla de Contenidos
A1: INDICE DE HERRAMIENTAS DE LOS INDICADORES SOSTENIBILIDAD DE LOS CAPS | E1: Ir a Resultados Finales
A2: Código | B2: Nombre/Descripción | C2: Haga click en el link siguiente | D2: OBSERVACION | E2: Fuente de la información
A3: 1 | B3: BAREMOS INDICE DE SOSTENIBILIDAD | C3: Ind.Sostenib. | D3: Esta tabla debe ser modificada antes de comenzar el análisis. | E3: No procede
B4: Resultado del Índice de Sostenibilidad obtenido | C4: Resultado Final | D4: Esta tabla se nutre de todas las pestañas anteriores. POR FAVOR NO MODIFICAR NADA. :) | E4: No procede
A5: 2 | B5: Listado de CAPS a evaluar | C5: Listado CAPS | D5: Completar nombres CAPS a evaluar.
A6: 3 | B6: Conformación de la JD | C6: Conformación JD | D6: Completar con en acta Constitutiva de la JD o la actualizada si hubo reestructuración. | E6: Acta constitutiva
A7: A. | B7: ORGANIZACIÓN | D7: Si no hay libro de actas no se puede completar este criterio
B8: Nº miembros activos JD | E8: Libro de Actas
B9: Participación de mujeres | C9: A.Organización | E9: Libro de Actas
B10: Capacidad de convocatoria | D10: Se asume la informacion facilitada por el caps | E10: Cartas/ Invitaciones
B11: Legalización | C11: A.Legalización | E11: Certificados oficiales
A12: B. | B12: CAPITAL SOCIAL
B13: Espacios comunitarios en los que la JD del CAPS participa | C13: B.CapitalSocial | E13: Entrevistas realizadas al CAPS
A14: C. | B14: AUTOGESTION
B15: Capacidad de resolución de problemas (administrativo, legal, organizativo, técnico) | C15: C.AutoGestionCAPS | E15: Cartas, informes
A16: D. | B16: RECUPERACIÓN DE COSTOS | C16: D.RecuperacióndeCostes | E16: Libros contables Reportes mensuales de la cuenta de ahorro
A17: E. | B17: OPERACIÓN Y MANTENIMIENTO
B18: Existencia de Plan de Operación y Mantenimiento. Realización del 60% de las acciones recogidas en el Plan. | C18: E.Ope y Manten | E18: Actividades recogidas en los Libros de actas. Perioricidad en función del RI
A19: F. | B19: SALUD COMUNITARIA Y AMBIENTAL | C19: F.Salud Comunit | E19: Reportes de actividades recogidas en los Libros de actas
A20: G. | B20: RENDICIÓN DE CUENTAS | C20: G.Rendición de cuentas | E20: Libros contables Libro de Actas
A21: H. | B21: CONSERVACIÓN DEL SISTEMA
B22: Conservación del sistema: MABE | C22: H.1 Estado_Conserv MABE | E22: Inspección ocular
B23: Conservación del sistema: MAG | C23: H.2.Estado_Conserv.MAG | E23: Inspección ocular
B24: Conservación del sistema: POZOS | C24: H.3.Estado_Consev.Pozos | E24: Inspección ocular
A26: I. | B26: GÉNERO
B27: Acciones positivas dirigidas a promover la participación activa de las mujeres y acciones contempladas en Reglamento Interno. | C27: I.Genero

Sheet Ind.Sostenib.
A1: Volver a Tabla de contenidos | F1: INDICES DE SOSTENIBILIDAD | J1: Ir a Resultados Finales
A3: MABE
A4: Años de Construcción del SAP | B4: Organización | C4: Nivel de Servicio de agua | D4: Recuperación de Costes | E4: Operación y Mantenimiento | F4: GIRH | G4: Rendición de Cuentas | H4: Estado y Conservación del SAP | I4: Incorporación del enfoque de Género. | J4: Autogestión | K4: Indice de Sostenibilidad
A5: 0 - 5 años | B5: 0.15 | C5: 0.05 | D5: 0.15 | E5: 0.15 | F5: 0.05 | G5: 0.1 | H5: 0.1 | I5: 0.1 | J5: 0.15 | K5: =SUM(B5:J5) -> 1
A6: 5 - 10 años | B6: 0.1 | C6: 0.05 | D6: 0.2 | E6: 0.2 | F6: 0.05 | G6: 0.1 | H6: 0.05 | I6: 0.1 | J6: 0.15 | K6: =SUM(B6:J6) -> 1
A7: más de 10 años | B7: 0.1 | C7: 0.05 | D7: 0.2 | E7: 0.15 | F7: 0.05 | G7: 0.1 | H7: 0.05 | I7: 0.1 | J7: 0.2 | K7: =SUM(B7:J7) -> 1
A10: MAG /POZOS
A11: Años de Construcción del SAP | B11: Organización | C11: Nivel de Servicio de agua | D11: Recuperación de Costes | E11: Operación y Mantenimiento | F11: GIRH | G11: Rendición de Cuentas | H11: Estado y Conservación del SAP | I11: Incorporación del enfoque de Género. | J11: Autogestión | K11: Indice de Sostenibilidad
A12: 0 - 5 años | B12: 0.15 | C12: 0.05 | D12: 0.15 | E12: 0.15 | F12: 0.05 | G12: 0.1 | H12: 0.1 | I12: 0.1 | J12: 0.15 | K12: =SUM(B12:J12) -> 1
A13: 5 - 10 años | B13: 0.15 | C13: 0.05 | D13: 0.15 | E13: 0.15 | F13: 0.1 | G13: 0.1 | H13: 0.05 | I13: 0.1 | J13: 0.15 | K13: =SUM(B13:J13) -> 1
A14: mas de 10 años | B14: 0.1 | C14: 0.05 | D14: 0.2 | E14: 0.1 | F14: 0.05 | G14: 0.15 | H14: 0.05 | I14: 0.1 | J14: 0.2 | K14: =SUM(B14:J14) -> 1
A17: Índices de Sostenibilidad
A18: De 0 - 59 | B18: Hay muchas debilidades en la gestión del CAPS y funcionamiento del SAP, y se esta en riesgo la sostenibilidad en el futuro
A19: De 60 - 79 | B19: El CAPS esta realizando acciones de gestión y administración del SAP que apuntan a la sostenibilidad
A20: De 80 - 100 | B20: El CAPS esta realizando acciones internas que garantizan la sostenibilidad y en cordinación con otros.

Sheet Listado CAPS
B1: Volver a Tabla de contenidos | C1: Actualizada a fecha de: dd/mm/aaaa | F1: Ir a Resultados Finales
A2: DEPARTAMENTO | B2: MUNICIPIO | C2: COMUNIDAD/ES | D2: CAPS | E2: TIPO DE SISTEMA | F2: TIEMPO DEL SISTEMA | G2: VVIENDAS ATENDIDAS | H2: POBLACIÓN ATENDIDA | I2: VIVIENDAS SIN SERVICIO | J2: POBLACIÓN SIN SERVICIO | K2: Tipo de sistema | L2: Tiempo del sistema
A3: Madriz | B3: Yalaguina | C3: Los Encuentros | D3: Los Encuentros | E3: MAG | F3: 1 | K3: MAG | L3: 1 | M3: entre 0-5 años
D4: B | K4: MABE | L4: 2 | M4: 5-10 años
D5: C | K5: POZO | L5: 3 | M5: más de 10 años
D6: D | K6: MIXTO (MABE-MAG)
D7: E | K7: POZO EXCAVADO
D8: F | K8: POZO PERFORADO
D9: G | K9: MANANTIAL
D10: H | K10: LLUVIA
D11: I | K11: SUPERFICIE
D12: J
D13: K
D14: L
D15: M
D16: N
D17: Ñ
D18: O
D19: P
D20: Q
D21: R
D22: S
D23: T
... D28: Y

Sheet Conformación JD
B1: Volver a Tabla de contenidos | C1: 0. ESTRUCTURA DE LA JD | T1: Ir a Resultados Finales
C2: Instrucciones: 1) Para el llenado de este formato se debe utilizar el Acta de conformación del CAPS No toque las celdas sombreadas
Z3: Ir a Hoja de I.Género
A4: Departamento | B4: Municipio | C4: Comunidad | D4: CAPS | E4: A fecha de | F4: Cargos JD
F5: Presidente | H5: Tesorero | J5: Secretario | L5: Fiscal | N5: Vocal_1 | P5: Vocal_2 | R5: Vocal_3 | T5: Vocal_4 | V5: Vocal_5 | X5: Miembros totales | Y5: Total de mujeres | Z5: Total de Mujeres en cargos de poder (Presi y Tesorera) | AA5: % de mujeres en la JD
F6: H | G6: M | H6: H | I6: M | J6: H | K6: M | L6: H | M6: M | N6: H | O6: M | P6: H | Q6: M | R6: H | S6: M | T6: H | U6: M | V6: H | W6: M
A7: ='Listado CAPS'!A3 -> Madriz | B7: ='Listado CAPS'!B3 -> Yalaguina | C7: ='Listado CAPS'!C3 -> Los Encuentros | D7: ='Listado CAPS'!D3 -> Los Encuentros | E7: 45083 | F7: 1 | I7: 1 | K7: 1 | L7: 1 | O7: 1 | X7: =SUM(F7:W7) -> 5 | Y7: =+SUM(G7+I7+K7+M7+O7+Q7+S7+U7+W7) -> 3 | Z7: =SUM(G7+I7) -> 1 | AA7: =IF(Y7=0,0,(Y7/X7)) -> 0.6
A8: ='Listado CAPS'!A4 -> 0 | B8: ='Listado CAPS'!B4 -> 0 | C8: ='Listado CAPS'!C4 -> 0 | D8: ='Listado CAPS'!D4 -> B | X8: =SUM(F8:W8) -> 0 | Y8: =+SUM(G8+I8+K8+M8+O8+Q8+S8+U8+W8) -> 0 | Z8: =SUM(G8+I8) -> 0 | AA8: =IF(Y8=0,0,(Y8/X8)) -> 0
A9: ='Listado CAPS'!A5 -> 0 | B9: ='Listado CAPS'!B5 -> 0 | C9: ='Listado CAPS'!C5 -> 0 | D9: ='Listado CAPS'!D5 -> C | X9: =SUM(F9:W9) -> 0 | Y9: =+SUM(G9+I9+K9+M9+O9+Q9+S9+U9+W9) -> 0 | Z9: =SUM(G9+I9) -> 0 | AA9: =IF(Y9=0,0,(Y9/X9)) -> 0
A10: ='Listado CAPS'!A6 -> 0 | B10: ='Listado CAPS'!B6 -> 0 | C10: ='Listado CAPS'!C6 -> 0 | D10: ='Listado CAPS'!D6 -> D | X10: =SUM(F10:W10) -> 0 | Y10: =+SUM(G10+I10+K10+M10+O10+Q10+S10+U10+W10) -> 0 | Z10: =SUM(G10+I10) -> 0 | AA10: =IF(Y10=0,0,(Y10/X10)) -> 0
A11: ='Listado CAPS'!A7 -> 0 | B11: ='Listado CAPS'!B7 -> 0 | C11: ='Listado CAPS'!C7 -> 0 | D11: ='Listado CAPS'!D7 -> E | X11: =SUM(F11:W11) -> 0 | Y11: =+SUM(G11+I11+K11+M11+O11+Q11+S11+U11+W11) -> 0 | Z11: =SUM(G11+I11) -> 0 | AA11: =IF(Y11=0,0,(Y11/X11)) -> 0
A12: ='Listado CAPS'!A8 -> 0 | B12: ='Listado CAPS'!B8 -> 0 | C12: ='Listado CAPS'!C8 -> 0 | D12: ='Listado CAPS'!D8 -> F | X12: =SUM(F12:W12) -> 0 | Y12: =+SUM(G12+I12+K12+M12+O12+Q12+S12+U12+W12) -> 0 | Z12: =SUM(G12+I12) -> 0 | AA12: =IF(Y12=0,0,(Y12/X12)) -> 0
A13: ='Listado CAPS'!A9 -> 0 | B13: ='Listado CAPS'!B9 -> 0 | C13: ='Listado CAPS'!C9 -> 0 | D13: ='Listado CAPS'!D9 -> G | X13: =SUM(F13:W13) -> 0 | Y13: =+SUM(G13+I13+K13+M13+O13+Q13+S13+U13+W13) -> 0 | Z13: =SUM(G13+I13) -> 0 | AA13: =IF(Y13=0,0,(Y13/X13)) -> 0
A14: ='Listado CAPS'!A10 -> 0 | B14: ='Listado CAPS'!B10 -> 0 | C14: ='Listado CAPS'!C10 -> 0 | D14: ='Listado CAPS'!D10 -> H | X14: =SUM(F14:W14) -> 0 | Y14: =+SUM(G14+I14+K14+M14+O14+Q14+S14+U14+W14) -> 0 | Z14: =SUM(G14+I14) -> 0 | AA14: =IF(Y14=0,0,(Y14/X14)) -> 0
A15: ='Listado CAPS'!A11 -> 0 | B15: ='Listado CAPS'!B11 -> 0 | C15: ='Listado CAPS'!C11 -> 0 | D15: ='Listado CAPS'!D11 -> I | X15: =SUM(F15:W15) -> 0 | Y15: =+SUM(G15+I15+K15+M15+O15+Q15+S15+U15+W15) -> 0 | Z15: =SUM(G15+I15) -> 0 | AA15: =IF(Y15=0,0,(Y15/X15)) -> 0
A16: ='Listado CAPS'!A12 -> 0 | B16: ='Listado CAPS'!B12 -> 0 | C16: ='Listado CAPS'!C12 -> 0 | D16: ='Listado CAPS'!D12 -> J | X16: =SUM(F16:W16) -> 0 | Y16: =+SUM(G16+I16+K16+M16+O16+Q16+S16+U16+W16) -> 0 | Z16: =SUM(G16+I16) -> 0 | AA16: =IF(Y16=0,0,(Y16/X16)) -> 0
A17: ='Listado CAPS'!A13 -> 0 | B17: ='Listado CAPS'!B13 -> 0 | C17: ='Listado CAPS'!C13 -> 0 | D17: ='Listado CAPS'!D13 -> K | X17: =SUM(F17:W17) -> 0 | Y17: =+SUM(G17+I17+K17+M17+O17+Q17+S17+U17+W17) -> 0 | Z17: =SUM(G17+I17) -> 0 | AA17: =IF(Y17=0,0,(Y17/X17)) -> 0
A18: ='Listado CAPS'!A14 -> 0 | B18: ='Listado CAPS'!B14 -> 0 | C18: ='Listado CAPS'!C14 -> 0 | D18: ='Listado CAPS'!D14 -> L | X18: =SUM(F18:W18) -> 0 | Y18: =+SUM(G18+I18+K18+M18+O18+Q18+S18+U18+W18) -> 0 | Z18: =SUM(G18+I18) -> 0 | AA18: =IF(Y18=0,0,(Y18/X18)) -> 0
A19: ='Listado CAPS'!A15 -> 0 | B19: ='Listado CAPS'!B15 -> 0 | C19: ='Listado CAPS'!C15 -> 0 | D19: ='Listado CAPS'!D15 -> M | X19: =SUM(F19:W19) -> 0 | Y19: =+SUM(G19+I19+K19+M19+O19+Q19+S19+U19+W19) -> 0 | Z19: =SUM(G19+I19) -> 0 | AA19: =IF(Y19=0,0,(Y19/X19)) -> 0
... A32: ='Listado CAPS'!A28 -> 0 | B32: ='Listado CAPS'!B28 -> 0 | C32: ='Listado CAPS'!C28 -> 0 | D32: ='Listado CAPS'!D28 -> Y | X32: =SUM(F32:W32) -> 0 | Y32: =+SUM(G32+I32+K32+M32+O32+Q32+S32+U32+W32) -> 0 | Z32: =SUM(G32+I32) -> 0 | AA32: =IF(Y32=0,0,(Y32/X32)) -> 0
E33: TOTAL: | F33: =SUM(F7:F32) -> 1 | G33: =SUM(G7:G32) -> 0 | H33: =SUM(H7:H32) -> 0 | I33: =SUM(I7:I32) -> 1 | J33: =SUM(J7:J32) -> 0 | K33: =SUM(K7:K32) -> 1 | L33: =SUM(L7:L32) -> 1 | M33: =SUM(M7:M32) -> 0 | ... W33: =SUM(W7:W32) -> 0 | X33: =SUM(F33:W33) -> 5 | Y33: =+SUM(G33+I33+K33+M33+O33+Q33+S33+U33+W33) -> 3 | Z33: =IF(SUM(Z7:Z32)=0,0,SUM(Z7:Z32)/COUNTIF(X7:X32,"<>0")) -> 1 | AA33: =IF(SUM(AA7:AA32)=0,0,SUM(AA7:AA32)/COUNTIF(Y7:Y32,"<>0")) -> 0.6

Sheet  A.Legalización 
C2: Volver a Tabla de contenidos | D2: A. LEGALIZACIÓN | M2: Ir a Resultados Finales
F3: Instrucciones: Rellene las columnas en blanco según cada caso (1 si es SI). No modifique la columna "Valor total" por que es la que esta relacionada con la hoja de Resultado final. | K3: Criterios: Si no esta legalizado valor cero, si sí lo esta entonces: al menos 2 de los permisos si es MAG o Pozo u otras, 3 si es MABE por la tarifa diferenciada.
A5: Departamento | B5: Municipio | C5: Comunidad | D5: CAPS | E5: Tipo de sistema | F5: Certificado Registro municipal | G5: Certificado INAA | H5: Certificado RUC | I5: Tarifa Diferenciada INE 03/09/2012 | J5: Legalización SAP (infraestructura/terrenos) | K5: Valor Total | L5: Medios de Verificación Existe? | M5: Nombre del Medio de Verificación
A6: ='Listado CAPS'!A3 -> Madriz | B6: ='Listado CAPS'!B3 -> Yalaguina | C6: ='Listado CAPS'!C3 -> Los Encuentros | D6: ='Listado CAPS'!D3 -> Los Encuentros | E6: ='Listado CAPS'!E3 -> MAG | F6: 1 | G6: 1 | J6: 1 | K6: =IF(J6<>1,0,IF(E6="MABE",IF(SUM(F6:J6)>=3,1,0),IF(E6="MAG",IF(SUM(F6:J6)>=2,1,0),IF(E6<>"MAG, MABE",IF(SUM(F6:J6)>=2,1,0))))) -> 1
A7: ='Listado CAPS'!A4 -> 0 | B7: ='Listado CAPS'!B4 -> 0 | C7: ='Listado CAPS'!C4 -> 0 | D7: ='Listado CAPS'!D4 -> B | K7: =IF(J7<>1,0,IF(E7="MABE",IF(SUM(F7:J7)>=3,1,0),IF(E7="MAG",IF(SUM(F7:J7)>=2,1,0),IF(E7<>"MAG, MABE",IF(SUM(F7:J7)>=2,1,0))))) -> 0
A8: ='Listado CAPS'!A5 -> 0 | B8: ='Listado CAPS'!B5 -> 0 | C8: ='Listado CAPS'!C5 -> 0 | D8: ='Listado CAPS'!D5 -> C | K8: =IF(J8<>1,0,IF(E8="MABE",IF(SUM(F8:J8)>=3,1,0),IF(E8="MAG",IF(SUM(F8:J8)>=2,1,0),IF(E8<>"MAG, MABE",IF(SUM(F8:J8)>=2,1,0))))) -> 0
A9: ='Listado CAPS'!A6 -> 0 | B9: ='Listado CAPS'!B6 -> 0 | C9: ='Listado CAPS'!C6 -> 0 | D9: ='Listado CAPS'!D6 -> D | K9: =IF(J9<>1,0,IF(E9="MABE",IF(SUM(F9:J9)>=3,1,0),IF(E9="MAG",IF(SUM(F9:J9)>=2,1,0),IF(E9<>"MAG, MABE",IF(SUM(F9:J9)>=2,1,0))))) -> 0
A10: ='Listado CAPS'!A7 -> 0 | B10: ='Listado CAPS'!B7 -> 0 | C10: ='Listado CAPS'!C7 -> 0 | D10: ='Listado CAPS'!D7 -> E | K10: =IF(J10<>1,0,IF(E10="MABE",IF(SUM(F10:J10)>=3,1,0),IF(E10="MAG",IF(SUM(F10:J10)>=2,1,0),IF(E10<>"MAG, MABE",IF(SUM(F10:J10)>=2,1,0))))) -> 0
A11: ='Listado CAPS'!A8 -> 0 | B11: ='Listado CAPS'!B8 -> 0 | C11: ='Listado CAPS'!C8 -> 0 | D11: ='Listado CAPS'!D8 -> F | K11: =IF(J11<>1,0,IF(E11="MABE",IF(SUM(F11:J11)>=3,1,0),IF(E11="MAG",IF(SUM(F11:J11)>=2,1,0),IF(E11<>"MAG, MABE",IF(SUM(F11:J11)>=2,1,0))))) -> 0
A12: ='Listado CAPS'!A9 -> 0 | B12: ='Listado CAPS'!B9 -> 0 | C12: ='Listado CAPS'!C9 -> 0 | D12: ='Listado CAPS'!D9 -> G | K12: =IF(J12<>1,0,IF(E12="MABE",IF(SUM(F12:J12)>=3,1,0),IF(E12="MAG",IF(SUM(F12:J12)>=2,1,0),IF(E12<>"MAG, MABE",IF(SUM(F12:J12)>=2,1,0))))) -> 0
A13: ='Listado CAPS'!A10 -> 0 | B13: ='Listado CAPS'!B10 -> 0 | C13: ='Listado CAPS'!C10 -> 0 | D13: ='Listado CAPS'!D10 -> H | K13: =IF(J13<>1,0,IF(E13="MABE",IF(SUM(F13:J13)>=3,1,0),IF(E13="MAG",IF(SUM(F13:J13)>=2,1,0),IF(E13<>"MAG, MABE",IF(SUM(F13:J13)>=2,1,0))))) -> 0
A14: ='Listado CAPS'!A11 -> 0 | B14: ='Listado CAPS'!B11 -> 0 | C14: ='Listado CAPS'!C11 -> 0 | D14: ='Listado CAPS'!D11 -> I | K14: =IF(J14<>1,0,IF(E14="MABE",IF(SUM(F14:J14)>=3,1,0),IF(E14="MAG",IF(SUM(F14:J14)>=2,1,0),IF(E14<>"MAG, MABE",IF(SUM(F14:J14)>=2,1,0))))) -> 0
A15: ='Listado CAPS'!A12 -> 0 | B15: ='Listado CAPS'!B12 -> 0 | C15: ='Listado CAPS'!C12 -> 0 | D15: ='Listado CAPS'!D12 -> J | K15: =IF(J15<>1,0,IF(E15="MABE",IF(SUM(F15:J15)>=3,1,0),IF(E15="MAG",IF(SUM(F15:J15)>=2,1,0),IF(E15<>"MAG, MABE",IF(SUM(F15:J15)>=2,1,0))))) -> 0
A16: ='Listado CAPS'!A13 -> 0 | B16: ='Listado CAPS'!B13 -> 0 | C16: ='Listado CAPS'!C13 -> 0 | D16: ='Listado CAPS'!D13 -> K | K16: =IF(J16<>1,0,IF(E16="MABE",IF(SUM(F16:J16)>=3,1,0),IF(E16="MAG",IF(SUM(F16:J16)>=2,1,0),IF(E16<>"MAG, MABE",IF(SUM(F16:J16)>=2,1,0))))) -> 0
A17: ='Listado CAPS'!A14 -> 0 | B17: ='Listado CAPS'!B14 -> 0 | C17: ='Listado CAPS'!C14 -> 0 | D17: ='Listado CAPS'!D14 -> L | K17: =IF(J17<>1,0,IF(E17="MABE",IF(SUM(F17:J17)>=3,1,0),IF(E17="MAG",IF(SUM(F17:J17)>=2,1,0),IF(E17<>"MAG, MABE",IF(SUM(F17:J17)>=2,1,0))))) -> 0
A18: ='Listado CAPS'!A15 -> 0 | B18: ='Listado CAPS'!B15 -> 0 | C18: ='Listado CAPS'!C15 -> 0 | D18: ='Listado CAPS'!D15 -> M | K18: =IF(J18<>1,0,IF(E18="MABE",IF(SUM(F18:J18)>=3,1,0),IF(E18="MAG",IF(SUM(F18:J18)>=2,1,0),IF(E18<>"MAG, MABE",IF(SUM(F18:J18)>=2,1,0))))) -> 0
... A25: ='Listado CAPS'!A22 -> 0 | B25: ='Listado CAPS'!B22 -> 0 | C25: ='Listado CAPS'!C22 -> 0 | D25: ='Listado CAPS'!D22 -> S | K25: =IF(J25<>1,0,IF(E25="MABE",IF(SUM(F25:J25)>=3,1,0),IF(E25="MAG",IF(SUM(F25:J25)>=2,1,0),IF(E25<>"MAG, MABE",IF(SUM(F25:J25)>=2,1,0))))) -> 0
A26: ='Listado CAPS'!A23 -> 0 | B26: ='Listado CAPS'!B23 -> 0 | C26: ='Listado CAPS'!C23 -> 0 | D26: ='Listado CAPS'!D23 -> T | K26: =IF(E26="MABE",IF(SUM(F26:J26)>=3,1,0),IF(E26="MAG",IF(SUM(F26:J26)>=2,1,0),IF(E26<>"MAG, MABE",IF(SUM(F26:J26)>=2,1,0)))) -> 0
A27: ='Listado CAPS'!A24 -> 0 | B27: ='Listado CAPS'!B24 -> 0 | C27: ='Listado CAPS'!C24 -> 0 | D27: ='Listado CAPS'!D24 -> U | K27: =IF(E27="MABE",IF(SUM(F27:J27)>=3,1,0),IF(E27="MAG",IF(SUM(F27:J27)>=2,1,0),IF(E27<>"MAG, MABE",IF(SUM(F27:J27)>=2,1,0)))) -> 0
A28: ='Listado CAPS'!A25 -> 0 | B28: ='Listado CAPS'!B25 -> 0 | C28: ='Listado CAPS'!C25 -> 0 | D28: ='Listado CAPS'!D25 -> V | K28: =IF(E28="MABE",IF(SUM(F28:J28)>=3,1,0),IF(E28="MAG",IF(SUM(F28:J28)>=2,1,0),IF(E28<>"MAG, MABE",IF(SUM(F28:J28)>=2,1,0)))) -> 0
A29: ='Listado CAPS'!A26 -> 0 | B29: ='Listado CAPS'!B26 -> 0 | C29: ='Listado CAPS'!C26 -> 0 | D29: ='Listado CAPS'!D26 -> W | K29: =IF(E29="MABE",IF(SUM(F29:J29)>=3,1,0),IF(E29="MAG",IF(SUM(F29:J29)>=2,1,0),IF(E29<>"MAG, MABE",IF(SUM(F29:J29)>=2,1,0)))) -> 0
A30: ='Listado CAPS'!A27 -> 0 | B30: ='Listado CAPS'!B27 -> 0 | C30: ='Listado CAPS'!C27 -> 0 | D30: ='Listado CAPS'!D27 -> X | K30: =IF(E30="MABE",IF(SUM(F30:J30)>=3,1,0),IF(E30="MAG",IF(SUM(F30:J30)>=2,1,0),IF(E30<>"MAG, MABE",IF(SUM(F30:J30)>=2,1,0)))) -> 0
A31: ='Listado CAPS'!A28 -> 0 | B31: ='Listado CAPS'!B28 -> 0 | C31: ='Listado CAPS'!C28 -> 0 | D31: ='Listado CAPS'!D28 -> Y | K31: =IF(E31="MABE",IF(SUM(F31:J31)>=3,1,0),IF(E31="MAG",IF(SUM(F31:J31)>=2,1,0),IF(E31<>"MAG, MABE",IF(SUM(F31:J31)>=2,1,0)))) -> 0
BM123: 1- El Diamante.
BM124: 2- La Breiera
BM125: 3- Valle de Suni
BM126: 4- El Espino
BM127: 5- San Marcos
BM128: 6- Los Arados
BM129: 7- Lomas de Sacacli
BM130: 8- Sacacli
BM131: 9- Estación Cerro Grande
BM132: 10- Valerio
BM133: 11- Yupali
BM134: 12- Gracalcan
... BM148: 26- El Barro
N383: 1- El Diamante.
N384: 2- La Breiera
N385: 3- Valle de Suni
N386: 4- El Espino
...

Sheet A.Org_CAPS
C1: Volver a Tabla de contenidos | D1: A. ORGANIZACIÓN DE LOS CAPS | AF1: Ir a Resultados Finales
D2: Instrucciones: 1) Para el llenado de este formato se debe utilizar el Libro de Actas. 2) Este formato se deberá repetir para cada CAPS. Se ha copiado esta tabla a continuación para el siguiente CAPS. 3) Digite los campos: nombre de la actividad, fecha, seleccione quién convoca y en la columna de quorum ponga 1 si hay quorum. (se considera quorum la asistencia de 50%+1); Digite el nùmero de cargos que participa con un 1. 4) El %de asistencia de mujeres en las asambleas se mete en %. Ejemplo: 40%. | R2: Criterio: Miembros activos: Que la suma del total de miembros sea igual o mayor que 4 para miembros activos en la toma de decisiones. Convocatoria: Al menos el 50% reuniones tienen que haber sido convocadas por CAPS. Mujeres: 50%.
A3: Departamento | B3: Municipio | C3: Comunidad | D3: CAPS | E3: No. | F3: Nombre de la actividad | G3: Fecha | H3: Quien Convoca? | I3: Quorum | J3: Valor de la convocatoria | K3: % de asistencia de mujeres en las asambleas | L3: Cargos JD
L4: Presidente | N4: Secretario/a | P4: Tesorero/a | R4: Fiscal | T4: Vocal_1 | V4: Vocal_2 | X4: Vocal_3 | Z4: Vocal_4 | AB4: Vocal_5 | AD4: Total de miembros activos (en%) | AE4: Total de miembros activos (en nº) | AF4: Total de Mujeres que participan | AG4: % De participación de la mujer | AH4: NOTAS
L5: H | M5: M | N5: H | O5: M | P5: H | Q5: M | R5: H | S5: M | T5: H | U5: M | V5: H | W5: M | X5: H | Y5: M | Z5: H | AA5: M | AB5: H | AC5: M | AJ5: CAPS
A6: ='Listado CAPS'!A3 -> Madriz | B6: ='Listado CAPS'!B3 -> Yalaguina | C6: ='Listado CAPS'!C3 -> Los Encuentros | D6: ='Listado CAPS'!D3 -> Los Encuentros | E6: 1 | F6: Asmablea de rendición de cuentas | G6: 45064 | H6: CAPS+OTROS | I6: 1 | J6: =IF(H6<>"OTROS",1,0)*IF(I6=1,1,0) -> 1 | K6: 0.6 | L6: 1 | O6: 1 | Q6: 1 | U6: 1 | AD6: =IF(SUM(L6:AC6)=0,0,SUM(L6:AC6)/'Conformación JD'!$X$7) -> 0.8 | AE6: =SUM(L6:AC6) -> 4 | AF6: =+AC6+AA6+Y6+W6+U6+S6+Q6+O6+M6 -> 3 | AG6: =IF(AE6=0,0,AF6/AE6) -> 0.75 | AJ6: CAPS+OTROS
E7: 2 | J7: =IF(H7<>"OTROS",1,0)*IF(I7=1,1,0) -> 0 | AD7: =IF(SUM(L7:AC7)=0,0,SUM(L7:AC7)/'Conformación JD'!$X$7) -> 0 | AE7: =SUM(L7:AC7) -> 0 | AF7: =+AC7+AA7+Y7+W7+U7+S7+Q7+O7+M7 -> 0 | AG7: =IF(AE7=0,0,AF7/AE7) -> 0 | AJ7: OTROS
E8: 3 | J8: =IF(H8<>"OTROS",1,0)*IF(I8=1,1,0) -> 0 | AD8: =IF(SUM(L8:AC8)=0,0,SUM(L8:AC8)/'Conformación JD'!$X$7) -> 0 | AE8: =SUM(L8:AC8) -> 0 | AF8: =+AC8+AA8+Y8+W8+U8+S8+Q8+O8+M8 -> 0 | AG8: =IF(AE8=0,0,AF8/AE8) -> 0
E9: 4 | J9: =IF(H9<>"OTROS",1,0)*IF(I9=1,1,0) -> 0 | AD9: =IF(SUM(L9:AC9)=0,0,SUM(L9:AC9)/'Conformación JD'!$X$7) -> 0 | AE9: =SUM(L9:AC9) -> 0 | AF9: =+AC9+AA9+Y9+W9+U9+S9+Q9+O9+M9 -> 0 | AG9: =IF(AE9=0,0,AF9/AE9) -> 0
E10: 5 | J10: =IF(H10<>"OTROS",1,0)*IF(I10=1,1,0) -> 0 | AD10: =IF(SUM(L10:AC10)=0,0,SUM(L10:AC10)/'Conformación JD'!$X$7) -> 0 | AE10: =SUM(L10:AC10) -> 0 | AF10: =+AC10+AA10+Y10+W10+U10+S10+Q10+O10+M10 -> 0 | AG10: =IF(AE10=0,0,AF10/AE10) -> 0
E11: 6 | J11: =IF(H11<>"OTROS",1,0)*IF(I11=1,1,0) -> 0 | AD11: =IF(SUM(L11:AC11)=0,0,SUM(L11:AC11)/'Conformación JD'!$X$7) -> 0 | AE11: =SUM(L11:AC11) -> 0 | AF11: =+AC11+AA11+Y11+W11+U11+S11+Q11+O11+M11 -> 0 | AG11: =IF(AE11=0,0,AF11/AE11) -> 0
E12: 7 | J12: =IF(H12<>"OTROS",1,0)*IF(I12=1,1,0) -> 0 | AD12: =IF(SUM(L12:AC12)=0,0,SUM(L12:AC12)/'Conformación JD'!$X$7) -> 0 | AE12: =SUM(L12:AC12) -> 0 | AF12: =+AC12+AA12+Y12+W12+U12+S12+Q12+O12+M12 -> 0 | AG12: =IF(AE12=0,0,AF12/AE12) -> 0
E13: 8 | J13: =IF(H13<>"OTROS",1,0)*IF(I13=1,1,0) -> 0 | AD13: =IF(SUM(L13:AC13)=0,0,SUM(L13:AC13)/'Conformación JD'!$X$7) -> 0 | AE13: =SUM(L13:AC13) -> 0 | AF13: =+AC13+AA13+Y13+W13+U13+S13+Q13+O13+M13 -> 0 | AG13: =IF(AE13=0,0,AF13/AE13) -> 0
E14: 9 | J14: =IF(H14<>"OTROS",1,0)*IF(I14=1,1,0) -> 0 | AD14: =IF(SUM(L14:AC14)=0,0,SUM(L14:AC14)/'Conformación JD'!$X$7) -> 0 | AE14: =SUM(L14:AC14) -> 0 | AF14: =+AC14+AA14+Y14+W14+U14+S14+Q14+O14+M14 -> 0 | AG14: =IF(AE14=0,0,AF14/AE14) -> 0
E15: 10 | J15: =IF(H15<>"OTROS",1,0)*IF(I15=1,1,0) -> 0 | AD15: =IF(SUM(L15:AC15)=0,0,SUM(L15:AC15)/'Conformación JD'!$X$7) -> 0 | AE15: =SUM(L15:AC15) -> 0 | AF15: =+AC15+AA15+Y15+W15+U15+S15+Q15+O15+M15 -> 0 | AG15: =IF(AE15=0,0,AF15/AE15) -> 0
E16: TOTAL | I16: =IF((COUNTIF(G6:G15,"<>"))<>0,SUM(I6:I15)/COUNTIF(G6:G15,"<>"),0) -> 1 | J16: =IF((COUNTIF(H6:H15,"<>"))<>0,SUM(J6:J15)/COUNTIF(H6:H15,"<>"),0) -> 1 | K16: =IF((COUNTIF(H6:H15,"<>"))<>0,SUM(K6:K15)/COUNTIF(H6:H15,"<>"),0) -> 0.6 | L16: =SUM(L6:L15) -> 1 | M16: =SUM(M6:M15) -> 0 | N16: =SUM(N6:N15) -> 0 | O16: =SUM(O6:O15) -> 1 | P16: =SUM(P6:P15) -> 0 | Q16: =SUM(Q6:Q15) -> 1 | R16: =SUM(R6:R15) -> 0 | S16: =SUM(S6:S15) -> 0 | ... AC16: =SUM(AC6:AC15) -> 0 | AD16: =IF(SUM(AD6:AD15)=0,0,SUM(AD6:AD15)/COUNTIF(AD6:AD15,"<>0")) -> 0.8 | AE16: =IF(SUM(AE6:AE15)=0,0,SUM(AE6:AE15)/COUNTIF(AE6:AE15,"<>0")) -> 4 | AF16: =IF(SUM(AF6:AF15)=0,0,SUM(AF6:AF15)/COUNTIF(AF6:AF15,"<>0")) -> 3 | AG16: =IF(SUM(AG6:AG15)=0,0,SUM(AG6:AG15)/COUNTIF(AD6:AD15,"<>0")) -> 0.75
A17: Departamento | B17: Municipio | C17: Comunidad | D17: CAPS | E17: No. | F17: Nombre de la actividad | G17: Fecha | H17: Quien Convoca? | I17: Quorum | J17: Valor de la convocatoria | K17: % de asistencia de mujeres en las asambleas | L17: Cargos JD
L18: Presidente | N18: Secretario/a | P18: Tesorero/a | R18: Fiscal | T18: Vocal_1 | V18: Vocal_2 | X18: Vocal_3 | Z18: Vocal_4 | AB18: Vocal_5 | AD18: Total de miembros activos (en%) | AE18: Total de miembros activos (en nº) | AF18: Total de Mujeres que participan | AG18: % De participación de la mujer | AH18: NOTAS
L19: H | M19: M | N19: H | O19: M | P19: H | Q19: M | R19: H | S19: M | T19: H | U19: M | V19: H | W19: M | X19: H | Y19: M | Z19: H | AA19: M | AB19: H | AC19: M
A20: ='Listado CAPS'!A17 -> 0 | B20: ='Listado CAPS'!B17 -> 0 | C20: ='Listado CAPS'!C17 -> 0 | D20: ='Listado CAPS'!D4 -> B | E20: 1 | J20: =IF(H20<>"OTROS",1,0)*IF(I20=1,1,0) -> 0 | AD20: =IF(SUM(L20:AC20)=0,0,SUM(L20:AC20)/'Conformación JD'!$X$8) -> 0 | AE20: =SUM(L20:AC20) -> 0 | AF20: =+AC20+AA20+Y20+W20+U20+S20+Q20+O20+M20 -> 0 | AG20: =IF(AE20=0,0,AF20/AE20) -> 0
E21: 2 | J21: =IF(H21<>"OTROS",1,0)*IF(I21=1,1,0) -> 0 | AD21: =IF(SUM(L21:AC21)=0,0,SUM(L21:AC21)/'Conformación JD'!$X$8) -> 0 | AE21: =SUM(L21:AC21) -> 0 | AF21: =+AC21+AA21+Y21+W21+U21+S21+Q21+O21+M21 -> 0 | AG21: =IF(AE21=0,0,AF21/AE21) -> 0
E22: 3 | J22: =IF(H22<>"OTROS",1,0)*IF(I22=1,1,0) -> 0 | AD22: =IF(SUM(L22:AC22)=0,0,SUM(L22:AC22)/'Conformación JD'!$X$8) -> 0 | AE22: =SUM(L22:AC22) -> 0 | AF22: =+AC22+AA22+Y22+W22+U22+S22+Q22+O22+M22 -> 0 | AG22: =IF(AE22=0,0,AF22/AE22) -> 0
E23: 4 | J23: =IF(H23<>"OTROS",1,0)*IF(I23=1,1,0) -> 0 | AD23: =IF(SUM(L23:AC23)=0,0,SUM(L23:AC23)/'Conformación JD'!$X$8) -> 0 | AE23: =SUM(L23:AC23) -> 0 | AF23: =+AC23+AA23+Y23+W23+U23+S23+Q23+O23+M23 -> 0 | AG23: =IF(AE23=0,0,AF23/AE23) -> 0
E24: 5 | J24: =IF(H24<>"OTROS",1,0)*IF(I24=1,1,0) -> 0 | AD24: =IF(SUM(L24:AC24)=0,0,SUM(L24:AC24)/'Conformación JD'!$X$8) -> 0 | AE24: =SUM(L24:AC24) -> 0 | AF24: =+AC24+AA24+Y24+W24+U24+S24+Q24+O24+M24 -> 0 | AG24: =IF(AE24=0,0,AF24/AE24) -> 0
E25: 6 | J25: =IF(H25<>"OTROS",1,0)*IF(I25=1,1,0) -> 0 | AD25: =IF(SUM(L25:AC25)=0,0,SUM(L25:AC25)/'Conformación JD'!$X$8) -> 0 | AE25: =SUM(L25:AC25) -> 0 | AF25: =+AC25+AA25+Y25+W25+U25+S25+Q25+O25+M25 -> 0 | AG25: =IF(AE25=0,0,AF25/AE25) -> 0
E26: 7 | J26: =IF(H26<>"OTROS",1,0)*IF(I26=1,1,0) -> 0 | AD26: =IF(SUM(L26:AC26)=0,0,SUM(L26:AC26)/'Conformación JD'!$X$8) -> 0 | AE26: =SUM(L26:AC26) -> 0 | AF26: =+AC26+AA26+Y26+W26+U26+S26+Q26+O26+M26 -> 0 | AG26: =IF(AE26=0,0,AF26/AE26) -> 0
E27: 8 | J27: =IF(H27<>"OTROS",1,0)*IF(I27=1,1,0) -> 0 | AD27: =IF(SUM(L27:AC27)=0,0,SUM(L27:AC27)/'Conformación JD'!$X$8) -> 0 | AE27: =SUM(L27:AC27) -> 0 | AF27: =+AC27+AA27+Y27+W27+U27+S27+Q27+O27+M27 -> 0 | AG27: =IF(AE27=0,0,AF27/AE27) -> 0
E28: 9 | J28: =IF(H28<>"OTROS",1,0)*IF(I28=1,1,0) -> 0 | AD28: =IF(SUM(L28:AC28)=0,0,SUM(L28:AC28)/'Conformación JD'!$X$8) -> 0 | AE28: =SUM(L28:AC28) -> 0 | AF28: =+AC28+AA28+Y28+W28+U28+S28+Q28+O28+M28 -> 0 | AG28: =IF(AE28=0,0,AF28/AE28) -> 0
E29: 10 | J29: =IF(H29<>"OTROS",1,0)*IF(I29=1,1,0) -> 0 | AD29: =IF(SUM(L29:AC29)=0,0,SUM(L29:AC29)/'Conformación JD'!$X$8) -> 0 | AE29: =SUM(L29:AC29) -> 0 | AF29: =+AC29+AA29+Y29+W29+U29+S29+Q29+O29+M29 -> 0 | AG29: =IF(AE29=0,0,AF29/AE29) -> 0
